{"kind": "VulnerabilityManifest", "apiVersion": "spdx.softwarecomposition.kubescape.io/v1beta1", "metadata": {"name": "replicaset-python-5964c9bcd8-python-3dc2-05fd", "namespace": "kubescape", "uid": "b0668275-53f9-42e4-80b3-9a7a96f4dbe4", "resourceVersion": "1", "creationTimestamp": "2025-09-22T14:06:25Z", "labels": {"kubescape.io/context": "filtered", "kubescape.io/sbom-type": "container", "kubescape.io/workload-api-group": "apps", "kubescape.io/workload-api-version": "v1", "kubescape.io/workload-container-name": "python", "kubescape.io/workload-kind": "Deployment", "kubescape.io/workload-name": "python"}, "annotations": {"kubescape.io/completion": "complete", "kubescape.io/image-id": "docker.io/library/python@sha256:4e8e9a59bf1b3ca8e030244bc5f801f23e41e37971907371da21191312087a07", "kubescape.io/image-tag": "docker.io/library/python@sha256:4e8e9a59bf1b3ca8e030244bc5f801f23e41e37971907371da21191312087a07", "kubescape.io/scan-id": "replicaset-python-5964c9bcd8-python-3dc2-05fd-v1-32-0-v0-99-1", "kubescape.io/status": "ready", "kubescape.io/workload-container-name": "python"}}, "spec": {"metadata": {"withRelevancy": true, "tool": {"name": "", "version": "v0.99.1", "databaseVersion": "8947f666e75c337773be86e0c6f7f4739c7549184aa994ae6236d5dbe666523b"}, "report": {"createdAt": null}}, "payload": {"matches": [{"vulnerability": {"id": "CVE-2007-4559", "dataSource": "https://nvd.nist.gov/vuln/detail/CVE-2007-4559", "namespace": "nvd:cpe", "severity": "Medium", "urls": ["http://mail.python.org/pipermail/python-dev/2007-August/074290.html", "http://mail.python.org/pipermail/python-dev/2007-August/074292.html", "http://secunia.com/advisories/26623", "http://www.vupen.com/english/advisories/2007/3022", "https://bugzilla.redhat.com/show_bug.cgi?id=263261", "https://lists.fedoraproject.org/archives/list/package-announce%40lists.fedoraproject.org/message/CVBB7NU3YIRRDOKLYVN647WPRR3IAKR6/", "https://lists.fedoraproject.org/archives/list/package-announce%40lists.fedoraproject.org/message/FI55PGL47ES3OU2FQPGEHOI2EK3S2OBH/", "https://lists.fedoraproject.org/archives/list/package-announce%40lists.fedoraproject.org/message/KA4Z44ZAI4SY7THCFBUDNT5EEFO4XQ3A/", "https://security.gentoo.org/glsa/202309-06", "http://mail.python.org/pipermail/python-dev/2007-August/074290.html", "http://mail.python.org/pipermail/python-dev/2007-August/074292.html", "http://secunia.com/advisories/26623", "http://www.vupen.com/english/advisories/2007/3022", "https://bugzilla.redhat.com/show_bug.cgi?id=263261", "https://lists.fedoraproject.org/archives/list/package-announce%40lists.fedoraproject.org/message/CVBB7NU3YIRRDOKLYVN647WPRR3IAKR6/", "https://lists.fedoraproject.org/archives/list/package-announce%40lists.fedoraproject.org/message/FI55PGL47ES3OU2FQPGEHOI2EK3S2OBH/", "https://lists.fedoraproject.org/archives/list/package-announce%40lists.fedoraproject.org/message/KA4Z44ZAI4SY7THCFBUDNT5EEFO4XQ3A/", "https://lists.fedoraproject.org/archives/list/package-announce@lists.fedoraproject.org/message/CVBB7NU3YIRRDOKLYVN647WPRR3IAKR6/", "https://lists.fedoraproject.org/archives/list/package-announce@lists.fedoraproject.org/message/FI55PGL47ES3OU2FQPGEHOI2EK3S2OBH/", "https://lists.fedoraproject.org/archives/list/package-announce@lists.fedoraproject.org/message/KA4Z44ZAI4SY7THCFBUDNT5EEFO4XQ3A/", "https://security.gentoo.org/glsa/202309-06"], "description": "Directory traversal vulnerability in the (1) extract and (2) extractall functions in the tarfile module in Python allows user-assisted remote attackers to overwrite arbitrary files via a .. (dot dot) sequence in filenames in a TAR archive, a related issue to CVE-2001-1267.", "cvss": [{"version": "2.0", "vector": "AV:N/AC:M/Au:N/C:P/I:P/A:P", "metrics": {"baseScore": 6.8, "exploitabilityScore": 8.6, "impactScore": 6.5}, "vendorMetadata": {}}, {"version": "3.1", "vector": "CVSS:3.1/AV:N/AC:L/PR:N/UI:N/S:U/C:H/I:H/A:H", "metrics": {"baseScore": 9.8, "exploitabilityScore": 3.9, "impactScore": 5.9}, "vendorMetadata": {}}], "fix": {"versions": ["3.6.16", "3.8.17", "3.9.17", "3.10.12", "3.11.4"], "state": "fixed"}, "advisories": null}, "relatedVulnerabilities": null, "matchDetails": [{"type": "cpe-match", "matcher": "stock-matcher", "searchedBy": {"namespace": "nvd:cpe", "cpes": ["cpe:2.3:a:python:python:3.11.3:*:*:*:*:*:*:*"], "package": {"name": "python", "version": "3.11.3"}}, "found": {"vulnerabilityID": "CVE-2007-4559", "versionConstraint": "< 3.6.16,>= 3.10.0, < 3.10.12,>= 3.11.0, < 3.11.4,>= 3.7.0, < 3.8.17,>= 3.9.0, < 3.9.17 (unknown)", "cpes": ["cpe:2.3:a:python:python:*:*:*:*:*:*:*:*"]}}], "artifact": {"name": "python", "version": "3.11.3", "type": "binary", "locations": [{"path": "/usr/local/lib/libpython3.11.so.1.0", "layerID": "sha256:8e0e498514c61f26d96e7289ba2cbda125238188f34251c3ac9ae542e5164cb8"}, {"path": "/usr/local/bin/python3.11", "layerID": "sha256:8e0e498514c61f26d96e7289ba2cbda125238188f34251c3ac9ae542e5164cb8"}], "language": "", "licenses": null, "cpes": ["cpe:2.3:a:python_software_foundation:python:3.11.3:*:*:*:*:*:*:*", "cpe:2.3:a:python:python:3.11.3:*:*:*:*:*:*:*"], "purl": "pkg:generic/python@3.11.3", "upstreams": null}}, {"vulnerability": {"id": "CVE-2024-6232", "dataSource": "https://nvd.nist.gov/vuln/detail/CVE-2024-6232", "namespace": "nvd:cpe", "severity": "High", "urls": ["https://github.com/python/cpython/commit/34ddb64d088dd7ccc321f6103d23153256caa5d4", "https://github.com/python/cpython/commit/4eaf4891c12589e3c7bdad5f5b076e4c8392dd06", "https://github.com/python/cpython/commit/743acbe872485dc18df4d8ab2dc7895187f062c4", "https://github.com/python/cpython/commit/7d1f50cd92ff7e10a1c15a8f591dde8a6843a64d", "https://github.com/python/cpython/commit/b4225ca91547aa97ed3aca391614afbb255bc877", "https://github.com/python/cpython/commit/d449caf8a179e3b954268b3a88eb9170be3c8fbf", "https://github.com/python/cpython/commit/ed3a49ea734ada357ff4442996fd4ae71d253373", "https://github.com/python/cpython/issues/121285", "https://github.com/python/cpython/pull/121286", "https://mail.python.org/archives/list/security-announce@python.org/thread/JRYFTPRHZRTLMZLWQEUHZSJXNHM4ACTY/", "http://www.openwall.com/lists/oss-security/2024/09/03/5", "https://security.netapp.com/advisory/ntap-20241018-0007/"], "description": "There is a MEDIUM severity vulnerability affecting CPython.\n\n\n\n\n\nRegular expressions that allowed excessive backtracking during tarfile.TarFile header parsing are vulnerable to ReDoS via specifically-crafted tar archives.", "cvss": [{"version": "3.1", "vector": "CVSS:3.1/AV:N/AC:L/PR:N/UI:N/S:U/C:N/I:N/A:H", "metrics": {"baseScore": 7.5, "exploitabilityScore": 3.9, "impactScore": 3.6}, "vendorMetadata": {}}, {"version": "3.1", "vector": "CVSS:3.1/AV:N/AC:L/PR:N/UI:N/S:U/C:N/I:N/A:H", "metrics": {"baseScore": 7.5, "exploitabilityScore": 3.9, "impactScore": 3.6}, "vendorMetadata": {}}], "fix": {"versions": ["3.8.20", "3.9.20", "3.10.15", "3.11.10", "3.12.6", "3.13.0rc2"], "state": "fixed"}, "advisories": null}, "relatedVulnerabilities": null, "matchDetails": [{"type": "cpe-match", "matcher": "stock-matcher", "searchedBy": {"namespace": "nvd:cpe", "cpes": ["cpe:2.3:a:python:python:3.11.3:*:*:*:*:*:*:*"], "package": {"name": "python", "version": "3.11.3"}}, "found": {"vulnerabilityID": "CVE-2024-6232", "versionConstraint": "< 3.8.20,>= 3.10, < 3.10.15,>= 3.11, < 3.11.10,>= 3.12, < 3.12.6,>= 3.13, < 3.13.0rc2,>= 3.9, < 3.9.20 (unknown)", "cpes": ["cpe:2.3:a:python:python:*:*:*:*:*:*:*:*"]}}], "artifact": {"name": "python", "version": "3.11.3", "type": "binary", "locations": [{"path": "/usr/local/lib/libpython3.11.so.1.0", "layerID": "sha256:8e0e498514c61f26d96e7289ba2cbda125238188f34251c3ac9ae542e5164cb8"}, {"path": "/usr/local/bin/python3.11", "layerID": "sha256:8e0e498514c61f26d96e7289ba2cbda125238188f34251c3ac9ae542e5164cb8"}], "language": "", "licenses": null, "cpes": ["cpe:2.3:a:python_software_foundation:python:3.11.3:*:*:*:*:*:*:*", "cpe:2.3:a:python:python:3.11.3:*:*:*:*:*:*:*"], "purl": "pkg:generic/python@3.11.3", "upstreams": null}}, {"vulnerability": {"id": "CVE-2023-24329", "dataSource": "https://nvd.nist.gov/vuln/detail/CVE-2023-24329", "namespace": "nvd:cpe", "severity": "High", "urls": ["https://github.com/python/cpython/issues/102153", "https://github.com/python/cpython/pull/99421", "https://lists.debian.org/debian-lts-announce/2023/09/msg00022.html", "https://lists.fedoraproject.org/archives/list/package-announce%40lists.fedoraproject.org/message/6PEVICI7YNGGMSL3UCMWGE66QFLATH72/", "https://lists.fedoraproject.org/archives/list/package-announce%40lists.fedoraproject.org/message/DSL6NSOAXWBJJ67XPLSSC74MNKZF3BBO/", "https://lists.fedoraproject.org/archives/list/package-announce%40lists.fedoraproject.org/message/EM2XLZSTXG44TMFXF4E6VTGKR2MQCW3G/", "https://lists.fedoraproject.org/archives/list/package-announce%40lists.fedoraproject.org/message/F2NY75GFDZ5T6YPN44D3VMFT5SUVTOTG/", "https://lists.fedoraproject.org/archives/list/package-announce%40lists.fedoraproject.org/message/GR5US3BYILYJ4SKBV6YBNPRUBAL5P2CN/", "https://lists.fedoraproject.org/archives/list/package-announce%40lists.fedoraproject.org/message/H23OSKC6UG6IWOQAUPW74YUHWRWVXJP7/", "https://lists.fedoraproject.org/archives/list/package-announce%40lists.fedoraproject.org/message/JZTLGV2HYFF4AMYJL25VDIGAIHCU7UPA/", "https://lists.fedoraproject.org/archives/list/package-announce%40lists.fedoraproject.org/message/LWC4WGXER5P6Q75RFGL7QUTPP3N5JR7T/", "https://lists.fedoraproject.org/archives/list/package-announce%40lists.fedoraproject.org/message/MZEHSXSCMA4WWQKXT6QV7AAR6SWNZ2VP/", "https://lists.fedoraproject.org/archives/list/package-announce%40lists.fedoraproject.org/message/O5SP4RT3RRS434ZS2HQKQJ3VZW7YPKYR/", "https://lists.fedoraproject.org/archives/list/package-announce%40lists.fedoraproject.org/message/OHHJHJRLEF3TDT2K3676CAUVRDD4CCMR/", "https://lists.fedoraproject.org/archives/list/package-announce%40lists.fedoraproject.org/message/PEUN6T22UJFXR7J5F6UUHCXXPKJ2DVHI/", "https://lists.fedoraproject.org/archives/list/package-announce%40lists.fedoraproject.org/message/PURM5CFDABEWAIWZFD2MQ7ZJGCPYSQ44/", "https://lists.fedoraproject.org/archives/list/package-announce%40lists.fedoraproject.org/message/Q3J5N24ECS4B6MJDRO6UAYU6GPLYBDCL/", "https://lists.fedoraproject.org/archives/list/package-announce%40lists.fedoraproject.org/message/QRQHN7RWJQJHYP6E5EKESOYP5VDSHZG4/", "https://lists.fedoraproject.org/archives/list/package-announce%40lists.fedoraproject.org/message/RA2MBEEES6L46OD64OBSVUUMGKNGMOWW/", "https://lists.fedoraproject.org/archives/list/package-announce%40lists.fedoraproject.org/message/T4IDB5OAR5Y4UK3HLMZBW4WEL2B7YFMJ/", "https://lists.fedoraproject.org/archives/list/package-announce%40lists.fedoraproject.org/message/TZH26JGNZ5XYPZ5SAU3NKSBSPRE5OHTG/", "https://lists.fedoraproject.org/archives/list/package-announce%40lists.fedoraproject.org/message/U2MZOJYGFCB5PPT6AKMAU72N7QOYWLBP/", "https://lists.fedoraproject.org/archives/list/package-announce%40lists.fedoraproject.org/message/UONZWLB4QVLQIY5CPDLEUEKH6WX4VQMC/", "https://lists.fedoraproject.org/archives/list/package-announce%40lists.fedoraproject.org/message/WTOAUJNDWZDRWVSXJ354AYZYKRMT56HU/", "https://pointernull.com/security/python-url-parse-problem.html", "https://security.netapp.com/advisory/ntap-20230324-0004/", "https://www.kb.cert.org/vuls/id/127587", "https://github.com/python/cpython/issues/102153", "https://github.com/python/cpython/pull/99421", "https://lists.debian.org/debian-lts-announce/2023/09/msg00022.html", "https://lists.fedoraproject.org/archives/list/package-announce%40lists.fedoraproject.org/message/6PEVICI7YNGGMSL3UCMWGE66QFLATH72/", "https://lists.fedoraproject.org/archives/list/package-announce%40lists.fedoraproject.org/message/DSL6NSOAXWBJJ67XPLSSC74MNKZF3BBO/", "https://lists.fedoraproject.org/archives/list/package-announce%40lists.fedoraproject.org/message/EM2XLZSTXG44TMFXF4E6VTGKR2MQCW3G/", "https://lists.fedoraproject.org/archives/list/package-announce%40lists.fedoraproject.org/message/F2NY75GFDZ5T6YPN44D3VMFT5SUVTOTG/", "https://lists.fedoraproject.org/archives/list/package-announce%40lists.fedoraproject.org/message/GR5US3BYILYJ4SKBV6YBNPRUBAL5P2CN/", "https://lists.fedoraproject.org/archives/list/package-announce%40lists.fedoraproject.org/message/H23OSKC6UG6IWOQAUPW74YUHWRWVXJP7/", "https://lists.fedoraproject.org/archives/list/package-announce%40lists.fedoraproject.org/message/JZTLGV2HYFF4AMYJL25VDIGAIHCU7UPA/", "https://lists.fedoraproject.org/archives/list/package-announce%40lists.fedoraproject.org/message/LWC4WGXER5P6Q75RFGL7QUTPP3N5JR7T/", "https://lists.fedoraproject.org/archives/list/package-announce%40lists.fedoraproject.org/message/MZEHSXSCMA4WWQKXT6QV7AAR6SWNZ2VP/", "https://lists.fedoraproject.org/archives/list/package-announce%40lists.fedoraproject.org/message/O5SP4RT3RRS434ZS2HQKQJ3VZW7YPKYR/", "https://lists.fedoraproject.org/archives/list/package-announce%40lists.fedoraproject.org/message/OHHJHJRLEF3TDT2K3676CAUVRDD4CCMR/", "https://lists.fedoraproject.org/archives/list/package-announce%40lists.fedoraproject.org/message/PEUN6T22UJFXR7J5F6UUHCXXPKJ2DVHI/", "https://lists.fedoraproject.org/archives/list/package-announce%40lists.fedoraproject.org/message/PURM5CFDABEWAIWZFD2MQ7ZJGCPYSQ44/", "https://lists.fedoraproject.org/archives/list/package-announce%40lists.fedoraproject.org/message/Q3J5N24ECS4B6MJDRO6UAYU6GPLYBDCL/", "https://lists.fedoraproject.org/archives/list/package-announce%40lists.fedoraproject.org/message/QRQHN7RWJQJHYP6E5EKESOYP5VDSHZG4/", "https://lists.fedoraproject.org/archives/list/package-announce%40lists.fedoraproject.org/message/RA2MBEEES6L46OD64OBSVUUMGKNGMOWW/", "https://lists.fedoraproject.org/archives/list/package-announce%40lists.fedoraproject.org/message/T4IDB5OAR5Y4UK3HLMZBW4WEL2B7YFMJ/", "https://lists.fedoraproject.org/archives/list/package-announce%40lists.fedoraproject.org/message/TZH26JGNZ5XYPZ5SAU3NKSBSPRE5OHTG/", "https://lists.fedoraproject.org/archives/list/package-announce%40lists.fedoraproject.org/message/U2MZOJYGFCB5PPT6AKMAU72N7QOYWLBP/", "https://lists.fedoraproject.org/archives/list/package-announce%40lists.fedoraproject.org/message/UONZWLB4QVLQIY5CPDLEUEKH6WX4VQMC/", "https://lists.fedoraproject.org/archives/list/package-announce%40lists.fedoraproject.org/message/WTOAUJNDWZDRWVSXJ354AYZYKRMT56HU/", "https://pointernull.com/security/python-url-parse-problem.html", "https://security.netapp.com/advisory/ntap-20230324-0004/", "https://www.kb.cert.org/vuls/id/127587"], "description": "An issue in the urllib.parse component of Python before 3.11.4 allows attackers to bypass blocklisting methods by supplying a URL that starts with blank characters.", "cvss": [{"version": "3.1", "vector": "CVSS:3.1/AV:N/AC:L/PR:N/UI:N/S:U/C:N/I:H/A:N", "metrics": {"baseScore": 7.5, "exploitabilityScore": 3.9, "impactScore": 3.6}, "vendorMetadata": {}}, {"version": "3.1", "vector": "CVSS:3.1/AV:N/AC:L/PR:N/UI:N/S:U/C:N/I:H/A:N", "metrics": {"baseScore": 7.5, "exploitabilityScore": 3.9, "impactScore": 3.6}, "vendorMetadata": {}}], "fix": {"versions": ["3.7.17", "3.8.17", "3.9.17", "3.10.12", "3.11.4"], "state": "fixed"}, "advisories": null}, "relatedVulnerabilities": null, "matchDetails": [{"type": "cpe-match", "matcher": "stock-matcher", "searchedBy": {"namespace": "nvd:cpe", "cpes": ["cpe:2.3:a:python:python:3.11.3:*:*:*:*:*:*:*"], "package": {"name": "python", "version": "3.11.3"}}, "found": {"vulnerabilityID": "CVE-2023-24329", "versionConstraint": "< 3.7.17,>= 3.10.0, < 3.10.12,>= 3.11.0, < 3.11.4,>= 3.8.0, < 3.8.17,>= 3.9.0, < 3.9.17 (unknown)", "cpes": ["cpe:2.3:a:python:python:*:*:*:*:*:*:*:*"]}}], "artifact": {"name": "python", "version": "3.11.3", "type": "binary", "locations": [{"path": "/usr/local/lib/libpython3.11.so.1.0", "layerID": "sha256:8e0e498514c61f26d96e7289ba2cbda125238188f34251c3ac9ae542e5164cb8"}, {"path": "/usr/local/bin/python3.11", "layerID": "sha256:8e0e498514c61f26d96e7289ba2cbda125238188f34251c3ac9ae542e5164cb8"}], "language": "", "licenses": null, "cpes": ["cpe:2.3:a:python_software_foundation:python:3.11.3:*:*:*:*:*:*:*", "cpe:2.3:a:python:python:3.11.3:*:*:*:*:*:*:*"], "purl": "pkg:generic/python@3.11.3", "upstreams": null}}, {"vulnerability": {"id": "CVE-2024-4032", "dataSource": "https://nvd.nist.gov/vuln/detail/CVE-2024-4032", "namespace": "nvd:cpe", "severity": "High", "urls": ["http://www.openwall.com/lists/oss-security/2024/06/17/3", "https://github.com/python/cpython/commit/22adf29da8d99933ffed8647d3e0726edd16f7f8", "https://github.com/python/cpython/commit/40d75c2b7f5c67e254d0a025e0f2e2c7ada7f69f", "https://github.com/python/cpython/commit/895f7e2ac23eff4743143beef0f0c5ac71ea27d3", "https://github.com/python/cpython/commit/ba431579efdcbaed7a96f2ac4ea0775879a332fb", "https://github.com/python/cpython/commit/c62c9e518b784fe44432a3f4fc265fb95b651906", "https://github.com/python/cpython/commit/f86b17ac511e68192ba71f27e752321a3252cee3", "https://github.com/python/cpython/issues/113171", "https://github.com/python/cpython/pull/113179", "https://mail.python.org/archives/list/security-announce@python.org/thread/NRUHDUS2IV2USIZM2CVMSFL6SCKU3RZA/", "https://security.netapp.com/advisory/ntap-20240726-0004/", "https://www.iana.org/assignments/iana-ipv4-special-registry/iana-ipv4-special-registry.xhtml", "https://www.iana.org/assignments/iana-ipv6-special-registry/iana-ipv6-special-registry.xhtml", "http://www.openwall.com/lists/oss-security/2024/06/17/3", "https://github.com/python/cpython/commit/22adf29da8d99933ffed8647d3e0726edd16f7f8", "https://github.com/python/cpython/commit/40d75c2b7f5c67e254d0a025e0f2e2c7ada7f69f", "https://github.com/python/cpython/commit/895f7e2ac23eff4743143beef0f0c5ac71ea27d3", "https://github.com/python/cpython/commit/ba431579efdcbaed7a96f2ac4ea0775879a332fb", "https://github.com/python/cpython/commit/c62c9e518b784fe44432a3f4fc265fb95b651906", "https://github.com/python/cpython/commit/f86b17ac511e68192ba71f27e752321a3252cee3", "https://github.com/python/cpython/issues/113171", "https://github.com/python/cpython/pull/113179", "https://mail.python.org/archives/list/security-announce@python.org/thread/NRUHDUS2IV2USIZM2CVMSFL6SCKU3RZA/", "https://security.netapp.com/advisory/ntap-20240726-0004/", "https://www.iana.org/assignments/iana-ipv4-special-registry/iana-ipv4-special-registry.xhtml", "https://www.iana.org/assignments/iana-ipv6-special-registry/iana-ipv6-special-registry.xhtml"], "description": "The \u201cipaddress\u201d module contained incorrect information about whether certain IPv4 and IPv6 addresses were designated as \u201cglobally reachable\u201d or \u201cprivate\u201d. This affected the is_private and is_global properties of the ipaddress.IPv4Address, ipaddress.IPv4Network, ipaddress.IPv6Address, and ipaddress.IPv6Network classes, where values wouldn\u2019t be returned in accordance with the latest information from the IANA Special-Purpose Address Registries.\n\nCPython 3.12.4 and 3.13.0a6 contain updated information from these registries and thus have the intended behavior.", "cvss": [{"version": "3.1", "vector": "CVSS:3.1/AV:N/AC:L/PR:N/UI:N/S:U/C:H/I:N/A:N", "metrics": {"baseScore": 7.5, "exploitabilityScore": 3.9, "impactScore": 3.6}, "vendorMetadata": {}}], "fix": {"versions": ["3.8.20", "3.9.20", "3.10.15", "3.11.10", "3.12.4", "3.13.0a6"], "state": "fixed"}, "advisories": null}, "relatedVulnerabilities": null, "matchDetails": [{"type": "cpe-match", "matcher": "stock-matcher", "searchedBy": {"namespace": "nvd:cpe", "cpes": ["cpe:2.3:a:python:python:3.11.3:*:*:*:*:*:*:*"], "package": {"name": "python", "version": "3.11.3"}}, "found": {"vulnerabilityID": "CVE-2024-4032", "versionConstraint": "< 3.8.20,>= 3.10.0, < 3.10.15,>= 3.11.0, < 3.11.10,>= 3.12.0, < 3.12.4,>= 3.13.0a1, < 3.13.0a6,>= 3.9.0, < 3.9.20 (unknown)", "cpes": ["cpe:2.3:a:python:python:*:*:*:*:*:*:*:*"]}}], "artifact": {"name": "python", "version": "3.11.3", "type": "binary", "locations": [{"path": "/usr/local/lib/libpython3.11.so.1.0", "layerID": "sha256:8e0e498514c61f26d96e7289ba2cbda125238188f34251c3ac9ae542e5164cb8"}, {"path": "/usr/local/bin/python3.11", "layerID": "sha256:8e0e498514c61f26d96e7289ba2cbda125238188f34251c3ac9ae542e5164cb8"}], "language": "", "licenses": null, "cpes": ["cpe:2.3:a:python_software_foundation:python:3.11.3:*:*:*:*:*:*:*", "cpe:2.3:a:python:python:3.11.3:*:*:*:*:*:*:*"], "purl": "pkg:generic/python@3.11.3", "upstreams": null}}, {"vulnerability": {"id": "CVE-2025-0938", "dataSource": "https://nvd.nist.gov/vuln/detail/CVE-2025-0938", "namespace": "nvd:cpe", "severity": "Medium", "urls": ["https://github.com/python/cpython/commit/526617ed68cde460236c973e5d0a8bad4de896ba", "https://github.com/python/cpython/commit/90e526ae67b172ed7c6c56e7edad36263b0f9403", "https://github.com/python/cpython/commit/a7084f6075c9595ba60119ce8c62f1496f50c568", "https://github.com/python/cpython/commit/b8b4b713c5f8ec0958c7ef8d29d6711889bc94ab", "https://github.com/python/cpython/commit/d89a5f6a6e65511a5f6e0618c4c30a7aa5aba56a", "https://github.com/python/cpython/commit/ff4e5c25666f63544071a6b075ae8b25c98b7a32", "https://github.com/python/cpython/issues/105704", "https://github.com/python/cpython/pull/129418", "https://mail.python.org/archives/list/security-announce@python.org/thread/K4EUG6EKV6JYFIC24BASYOZS4M5XOQIB/", "https://security.netapp.com/advisory/ntap-20250314-0002/"], "description": "The Python standard library functions `urllib.parse.urlsplit` and `urlparse` accepted domain names that included square brackets which isn't valid according to RFC 3986. Square brackets are only meant to be used as delimiters for specifying IPv6 and IPvFuture hosts in URLs. This could result in differential parsing across the Python URL parser and other specification-compliant URL parsers.", "cvss": [{"version": "4.0", "vector": "CVSS:4.0/AV:N/AC:H/AT:P/PR:N/UI:N/VC:N/VI:L/VA:N/SC:N/SI:L/SA:N/E:X/CR:X/IR:X/AR:X/MAV:X/MAC:X/MAT:X/MPR:X/MUI:X/MVC:X/MVI:X/MVA:X/MSC:X/MSI:X/MSA:X/S:X/AU:X/R:X/V:X/RE:X/U:X", "metrics": {"baseScore": 6.3}, "vendorMetadata": {}}], "fix": {"versions": ["3.9.22", "3.10.17", "3.11.12", "3.12.9", "3.13.2", "3.14.0a5"], "state": "fixed"}, "advisories": null}, "relatedVulnerabilities": null, "matchDetails": [{"type": "cpe-match", "matcher": "stock-matcher", "searchedBy": {"namespace": "nvd:cpe", "cpes": ["cpe:2.3:a:python:python:3.11.3:*:*:*:*:*:*:*"], "package": {"name": "python", "version": "3.11.3"}}, "found": {"vulnerabilityID": "CVE-2025-0938", "versionConstraint": "< 3.9.22,>= 3.10.0, < 3.10.17,>= 3.11.0, < 3.11.12,>= 3.12.0, < 3.12.9,>= 3.13.0, < 3.13.2,>= 3.14.0a1, < 3.14.0a5 (unknown)", "cpes": ["cpe:2.3:a:python:python:*:*:*:*:*:*:*:*"]}}], "artifact": {"name": "python", "version": "3.11.3", "type": "binary", "locations": [{"path": "/usr/local/lib/libpython3.11.so.1.0", "layerID": "sha256:8e0e498514c61f26d96e7289ba2cbda125238188f34251c3ac9ae542e5164cb8"}, {"path": "/usr/local/bin/python3.11", "layerID": "sha256:8e0e498514c61f26d96e7289ba2cbda125238188f34251c3ac9ae542e5164cb8"}], "language": "", "licenses": null, "cpes": ["cpe:2.3:a:python_software_foundation:python:3.11.3:*:*:*:*:*:*:*", "cpe:2.3:a:python:python:3.11.3:*:*:*:*:*:*:*"], "purl": "pkg:generic/python@3.11.3", "upstreams": null}}, {"vulnerability": {"id": "CVE-2024-7592", "dataSource": "https://nvd.nist.gov/vuln/detail/CVE-2024-7592", "namespace": "nvd:cpe", "severity": "High", "urls": ["https://github.com/python/cpython/commit/391e5626e3ee5af267b97e37abc7475732e67621", "https://github.com/python/cpython/commit/44e458357fca05ca0ae2658d62c8c595b048b5ef", "https://github.com/python/cpython/commit/a77ab24427a18bff817025adb03ca920dc3f1a06", "https://github.com/python/cpython/commit/b2f11ca7667e4d57c71c1c88b255115f16042d9a", "https://github.com/python/cpython/commit/d4ac921a4b081f7f996a5d2b101684b67ba0ed7f", "https://github.com/python/cpython/commit/d662e2db2605515a767f88ad48096b8ac623c774", "https://github.com/python/cpython/commit/dcc3eaef98cd94d6cb6cb0f44bd1c903d04f33b1", "https://github.com/python/cpython/issues/123067", "https://github.com/python/cpython/pull/123075", "https://mail.python.org/archives/list/security-announce@python.org/thread/HXJAAAALNUNGCQUS2W7WR6GFIZIHFOOK/", "https://security.netapp.com/advisory/ntap-20241018-0006/"], "description": "There is a LOW severity vulnerability affecting CPython, specifically the\n'http.cookies' standard library module.\n\n\nWhen parsing cookies that contained backslashes for quoted characters in\nthe cookie value, the parser would use an algorithm with quadratic\ncomplexity, resulting in excess CPU resources being used while parsing the\nvalue.", "cvss": [{"version": "3.1", "vector": "CVSS:3.1/AV:N/AC:L/PR:N/UI:N/S:U/C:N/I:N/A:H", "metrics": {"baseScore": 7.5, "exploitabilityScore": 3.9, "impactScore": 3.6}, "vendorMetadata": {}}, {"version": "3.1", "vector": "CVSS:3.1/AV:N/AC:L/PR:N/UI:N/S:U/C:N/I:N/A:H", "metrics": {"baseScore": 7.5, "exploitabilityScore": 3.9, "impactScore": 3.6}, "vendorMetadata": {}}], "fix": {"versions": ["3.8.20", "3.9.20", "3.10.15", "3.11.10", "3.12.6", "3.13.0rc2"], "state": "fixed"}, "advisories": null}, "relatedVulnerabilities": null, "matchDetails": [{"type": "cpe-match", "matcher": "stock-matcher", "searchedBy": {"namespace": "nvd:cpe", "cpes": ["cpe:2.3:a:python:python:3.11.3:*:*:*:*:*:*:*"], "package": {"name": "python", "version": "3.11.3"}}, "found": {"vulnerabilityID": "CVE-2024-7592", "versionConstraint": "< 3.8.20,>= 3.10, < 3.10.15,>= 3.11, < 3.11.10,>= 3.12, < 3.12.6,>= 3.13.0a1, < 3.13.0rc2,>= 3.9, < 3.9.20 (unknown)", "cpes": ["cpe:2.3:a:python:python:*:*:*:*:*:*:*:*"]}}], "artifact": {"name": "python", "version": "3.11.3", "type": "binary", "locations": [{"path": "/usr/local/lib/libpython3.11.so.1.0", "layerID": "sha256:8e0e498514c61f26d96e7289ba2cbda125238188f34251c3ac9ae542e5164cb8"}, {"path": "/usr/local/bin/python3.11", "layerID": "sha256:8e0e498514c61f26d96e7289ba2cbda125238188f34251c3ac9ae542e5164cb8"}], "language": "", "licenses": null, "cpes": ["cpe:2.3:a:python_software_foundation:python:3.11.3:*:*:*:*:*:*:*", "cpe:2.3:a:python:python:3.11.3:*:*:*:*:*:*:*"], "purl": "pkg:generic/python@3.11.3", "upstreams": null}}, {"vulnerability": {"id": "CVE-2024-0397", "dataSource": "https://nvd.nist.gov/vuln/detail/CVE-2024-0397", "namespace": "nvd:cpe", "severity": "High", "urls": ["http://www.openwall.com/lists/oss-security/2024/06/17/2", "https://github.com/python/cpython/commit/01c37f1d0714f5822d34063ca7180b595abf589d", "https://github.com/python/cpython/commit/29c97287d205bf2f410f4895ebce3f43b5160524", "https://github.com/python/cpython/commit/37324b421b72b7bc9934e27aba85d48d4773002e", "https://github.com/python/cpython/commit/542f3272f56f31ed04e74c40635a913fbc12d286", "https://github.com/python/cpython/commit/b228655c227b2ca298a8ffac44d14ce3d22f6faa", "https://github.com/python/cpython/commit/bce693111bff906ccf9281c22371331aaff766ab", "https://github.com/python/cpython/issues/114572", "https://github.com/python/cpython/pull/114573", "https://mail.python.org/archives/list/security-announce@python.org/thread/BMAK5BCGKYWNJOACVUSLUF6SFGBIM4VP/", "http://www.openwall.com/lists/oss-security/2024/06/17/2", "https://github.com/python/cpython/commit/01c37f1d0714f5822d34063ca7180b595abf589d", "https://github.com/python/cpython/commit/29c97287d205bf2f410f4895ebce3f43b5160524", "https://github.com/python/cpython/commit/37324b421b72b7bc9934e27aba85d48d4773002e", "https://github.com/python/cpython/commit/542f3272f56f31ed04e74c40635a913fbc12d286", "https://github.com/python/cpython/commit/b228655c227b2ca298a8ffac44d14ce3d22f6faa", "https://github.com/python/cpython/commit/bce693111bff906ccf9281c22371331aaff766ab", "https://github.com/python/cpython/issues/114572", "https://github.com/python/cpython/pull/114573", "https://mail.python.org/archives/list/security-announce@python.org/thread/BMAK5BCGKYWNJOACVUSLUF6SFGBIM4VP/", "https://security.netapp.com/advisory/ntap-20250411-0006/"], "description": "A defect was discovered in the Python \u201cssl\u201d module where there is a memory\nrace condition with the ssl.SSLContext methods \u201ccert_store_stats()\u201d and\n\u201cget_ca_certs()\u201d. The race condition can be triggered if the methods are\ncalled at the same time as certificates are loaded into the SSLContext,\nsuch as during the TLS handshake with a certificate directory configured.\nThis issue is fixed in CPython 3.10.14, 3.11.9, 3.12.3, and 3.13.0a5.", "cvss": [{"version": "3.1", "vector": "CVSS:3.1/AV:N/AC:H/PR:N/UI:N/S:U/C:H/I:N/A:H", "metrics": {"baseScore": 7.4, "exploitabilityScore": 2.3, "impactScore": 5.2}, "vendorMetadata": {}}], "fix": {"versions": ["3.8.20", "3.9.20", "3.10.14", "3.11.9", "3.12.3", "3.13.0a5"], "state": "fixed"}, "advisories": null}, "relatedVulnerabilities": null, "matchDetails": [{"type": "cpe-match", "matcher": "stock-matcher", "searchedBy": {"namespace": "nvd:cpe", "cpes": ["cpe:2.3:a:python:python:3.11.3:*:*:*:*:*:*:*"], "package": {"name": "python", "version": "3.11.3"}}, "found": {"vulnerabilityID": "CVE-2024-0397", "versionConstraint": "< 3.8.20,>= 3.10.0, < 3.10.14,>= 3.11.0, < 3.11.9,>= 3.12.0, < 3.12.3,>= 3.13.0a1, < 3.13.0a5,>= 3.9.0, < 3.9.20 (unknown)", "cpes": ["cpe:2.3:a:python:python:*:*:*:*:*:*:*:*"]}}], "artifact": {"name": "python", "version": "3.11.3", "type": "binary", "locations": [{"path": "/usr/local/lib/libpython3.11.so.1.0", "layerID": "sha256:8e0e498514c61f26d96e7289ba2cbda125238188f34251c3ac9ae542e5164cb8"}, {"path": "/usr/local/bin/python3.11", "layerID": "sha256:8e0e498514c61f26d96e7289ba2cbda125238188f34251c3ac9ae542e5164cb8"}], "language": "", "licenses": null, "cpes": ["cpe:2.3:a:python_software_foundation:python:3.11.3:*:*:*:*:*:*:*", "cpe:2.3:a:python:python:3.11.3:*:*:*:*:*:*:*"], "purl": "pkg:generic/python@3.11.3", "upstreams": null}}, {"vulnerability": {"id": "CVE-2024-11168", "dataSource": "https://nvd.nist.gov/vuln/detail/CVE-2024-11168", "namespace": "nvd:cpe", "severity": "Medium", "urls": ["https://github.com/python/cpython/commit/29f348e232e82938ba2165843c448c2b291504c5", "https://github.com/python/cpython/commit/634ded45545ce8cbd6fd5d49785613dd7fa9b89e", "https://github.com/python/cpython/commit/b2171a2fd41416cf68afd67460578631d755a550", "https://github.com/python/cpython/commit/ddca2953191c67a12b1f19d6bca41016c6ae7132", "https://github.com/python/cpython/issues/103848", "https://github.com/python/cpython/pull/103849", "https://mail.python.org/archives/list/security-announce@python.org/thread/XPWB6XVZ5G5KGEI63M4AWLIEUF5BPH4T/", "https://security.netapp.com/advisory/ntap-20250411-0004/"], "description": "The urllib.parse.urlsplit() and urlparse() functions improperly validated bracketed hosts (`[]`), allowing hosts that weren't IPv6 or IPvFuture. This behavior was not conformant to RFC 3986 and potentially enabled SSRF if a URL is processed by more than one URL parser.", "cvss": [{"version": "4.0", "vector": "CVSS:4.0/AV:N/AC:H/AT:P/PR:N/UI:N/VC:N/VI:L/VA:N/SC:N/SI:L/SA:N/E:X/CR:X/IR:X/AR:X/MAV:X/MAC:X/MAT:X/MPR:X/MUI:X/MVC:X/MVI:X/MVA:X/MSC:X/MSI:X/MSA:X/S:X/AU:N/R:X/V:X/RE:X/U:X", "metrics": {"baseScore": 6.3}, "vendorMetadata": {}}, {"version": "3.1", "vector": "CVSS:3.1/AV:N/AC:H/PR:N/UI:N/S:U/C:N/I:L/A:N", "metrics": {"baseScore": 3.7, "exploitabilityScore": 2.3, "impactScore": 1.5}, "vendorMetadata": {}}], "fix": {"versions": ["3.9.21", "3.10.16", "3.11.4", "3.12.0b1"], "state": "fixed"}, "advisories": null}, "relatedVulnerabilities": null, "matchDetails": [{"type": "cpe-match", "matcher": "stock-matcher", "searchedBy": {"namespace": "nvd:cpe", "cpes": ["cpe:2.3:a:python:python:3.11.3:*:*:*:*:*:*:*"], "package": {"name": "python", "version": "3.11.3"}}, "found": {"vulnerabilityID": "CVE-2024-11168", "versionConstraint": "< 3.9.21,>= 3.10.0, < 3.10.16,>= 3.11.0, < 3.11.4,>= 3.12.0a1, < 3.12.0b1 (unknown)", "cpes": ["cpe:2.3:a:python:python:*:*:*:*:*:*:*:*"]}}], "artifact": {"name": "python", "version": "3.11.3", "type": "binary", "locations": [{"path": "/usr/local/lib/libpython3.11.so.1.0", "layerID": "sha256:8e0e498514c61f26d96e7289ba2cbda125238188f34251c3ac9ae542e5164cb8"}, {"path": "/usr/local/bin/python3.11", "layerID": "sha256:8e0e498514c61f26d96e7289ba2cbda125238188f34251c3ac9ae542e5164cb8"}], "language": "", "licenses": null, "cpes": ["cpe:2.3:a:python_software_foundation:python:3.11.3:*:*:*:*:*:*:*", "cpe:2.3:a:python:python:3.11.3:*:*:*:*:*:*:*"], "purl": "pkg:generic/python@3.11.3", "upstreams": null}}, {"vulnerability": {"id": "CVE-2023-40217", "dataSource": "https://nvd.nist.gov/vuln/detail/CVE-2023-40217", "namespace": "nvd:cpe", "severity": "Medium", "urls": ["https://lists.debian.org/debian-lts-announce/2023/09/msg00022.html", "https://lists.debian.org/debian-lts-announce/2023/10/msg00017.html", "https://mail.python.org/archives/list/security-announce%40python.org/thread/PEPLII27KYHLF4AK3ZQGKYNCRERG4YXY/", "https://security.netapp.com/advisory/ntap-20231006-0014/", "https://www.python.org/dev/security/", "https://lists.debian.org/debian-lts-announce/2023/09/msg00022.html", "https://lists.debian.org/debian-lts-announce/2023/10/msg00017.html", "https://mail.python.org/archives/list/security-announce%40python.org/thread/PEPLII27KYHLF4AK3ZQGKYNCRERG4YXY/", "https://security.netapp.com/advisory/ntap-20231006-0014/", "https://www.python.org/dev/security/"], "description": "An issue was discovered in Python before 3.8.18, 3.9.x before 3.9.18, 3.10.x before 3.10.13, and 3.11.x before 3.11.5. It primarily affects servers (such as HTTP servers) that use TLS client authentication. If a TLS server-side socket is created, receives data into the socket buffer, and then is closed quickly, there is a brief window where the SSLSocket instance will detect the socket as \"not connected\" and won't initiate a handshake, but buffered data will still be readable from the socket buffer. This data will not be authenticated if the server-side TLS peer is expecting client certificate authentication, and is indistinguishable from valid TLS stream data. Data is limited in size to the amount that will fit in the buffer. (The TLS connection cannot directly be used for data exfiltration because the vulnerable code path requires that the connection be closed on initialization of the SSLSocket.)", "cvss": [{"version": "3.1", "vector": "CVSS:3.1/AV:N/AC:L/PR:N/UI:N/S:U/C:L/I:N/A:N", "metrics": {"baseScore": 5.3, "exploitabilityScore": 3.9, "impactScore": 1.5}, "vendorMetadata": {}}], "fix": {"versions": ["3.8.18", "3.9.18", "3.10.13", "3.11.5"], "state": "fixed"}, "advisories": null}, "relatedVulnerabilities": null, "matchDetails": [{"type": "cpe-match", "matcher": "stock-matcher", "searchedBy": {"namespace": "nvd:cpe", "cpes": ["cpe:2.3:a:python:python:3.11.3:*:*:*:*:*:*:*"], "package": {"name": "python", "version": "3.11.3"}}, "found": {"vulnerabilityID": "CVE-2023-40217", "versionConstraint": "< 3.8.18,>= 3.10.0, < 3.10.13,>= 3.11.0, < 3.11.5,>= 3.9.0, < 3.9.18 (unknown)", "cpes": ["cpe:2.3:a:python:python:*:*:*:*:*:*:*:*"]}}], "artifact": {"name": "python", "version": "3.11.3", "type": "binary", "locations": [{"path": "/usr/local/lib/libpython3.11.so.1.0", "layerID": "sha256:8e0e498514c61f26d96e7289ba2cbda125238188f34251c3ac9ae542e5164cb8"}, {"path": "/usr/local/bin/python3.11", "layerID": "sha256:8e0e498514c61f26d96e7289ba2cbda125238188f34251c3ac9ae542e5164cb8"}], "language": "", "licenses": null, "cpes": ["cpe:2.3:a:python_software_foundation:python:3.11.3:*:*:*:*:*:*:*", "cpe:2.3:a:python:python:3.11.3:*:*:*:*:*:*:*"], "purl": "pkg:generic/python@3.11.3", "upstreams": null}}, {"vulnerability": {"id": "CVE-2025-4517", "dataSource": "https://nvd.nist.gov/vuln/detail/CVE-2025-4517", "namespace": "nvd:cpe", "severity": "Critical", "urls": ["https://gist.github.com/sethmlarson/52398e33eff261329a0180ac1d54f42f", "https://github.com/python/cpython/commit/19de092debb3d7e832e5672cc2f7b788d35951da", "https://github.com/python/cpython/commit/28463dba112af719df1e8b0391c46787ad756dd9", "https://github.com/python/cpython/commit/3612d8f51741b11f36f8fb0494d79086bac9390a", "https://github.com/python/cpython/commit/4633f3f497b1ff70e4a35b6fe2c907cbe2d4cb2e", "https://github.com/python/cpython/commit/9c1110ef6652687d7c55f590f909720eddde965a", "https://github.com/python/cpython/commit/9e0ac76d96cf80b49055f6d6b9a6763fb9215c2a", "https://github.com/python/cpython/commit/aa9eb5f757ceff461e6e996f12c89e5d9b583b01", "https://github.com/python/cpython/commit/dd8f187d0746da151e0025c51680979ac5b4cfb1", "https://github.com/python/cpython/issues/135034", "https://github.com/python/cpython/pull/135037", "https://mail.python.org/archives/list/security-announce@python.org/thread/MAXIJJCUUMCL7ATZNDVEGGHUMQMUUKLG/"], "description": "Allows arbitrary filesystem writes outside the extraction directory during extraction with filter=\"data\".\n\n\nYou are affected by this vulnerability if using the tarfile\u00a0module to extract untrusted tar archives using TarFile.extractall()\u00a0or TarFile.extract()\u00a0using the filter=\u00a0parameter with a value of \"data\"\u00a0or \"tar\". See the tarfile  extraction filters documentation https://docs.python.org/3/library/tarfile.html#tarfile-extraction-filter \u00a0for more information.\n\nNote that for Python 3.14 or later the default value of filter=\u00a0changed from \"no filtering\" to `\"data\", so if you are relying on this new default behavior then your usage is also affected.\n\nNote that none of these vulnerabilities significantly affect the installation of source distributions which are tar archives as source distributions already allow arbitrary code execution during the build process. However when evaluating source distributions it's important to avoid installing source distributions with suspicious links.", "cvss": [{"version": "3.1", "vector": "CVSS:3.1/AV:N/AC:L/PR:N/UI:N/S:U/C:H/I:H/A:L", "metrics": {"baseScore": 9.4, "exploitabilityScore": 3.9, "impactScore": 5.5}, "vendorMetadata": {}}], "fix": {"versions": ["3.9.23", "3.10.18", "3.11.13", "3.12.11", "3.13.4", "3.14.0b3"], "state": "fixed"}, "advisories": null}, "relatedVulnerabilities": null, "matchDetails": [{"type": "cpe-match", "matcher": "stock-matcher", "searchedBy": {"namespace": "nvd:cpe", "cpes": ["cpe:2.3:a:python:python:3.11.3:*:*:*:*:*:*:*"], "package": {"name": "python", "version": "3.11.3"}}, "found": {"vulnerabilityID": "CVE-2025-4517", "versionConstraint": "< 3.9.23,>= 3.10.0, < 3.10.18,>= 3.11.0, < 3.11.13,>= 3.12.0, < 3.12.11,>= 3.13.0, < 3.13.4,>= 3.14.0a1, < 3.14.0b3 (unknown)", "cpes": ["cpe:2.3:a:python:python:*:*:*:*:*:*:*:*"]}}], "artifact": {"name": "python", "version": "3.11.3", "type": "binary", "locations": [{"path": "/usr/local/lib/libpython3.11.so.1.0", "layerID": "sha256:8e0e498514c61f26d96e7289ba2cbda125238188f34251c3ac9ae542e5164cb8"}, {"path": "/usr/local/bin/python3.11", "layerID": "sha256:8e0e498514c61f26d96e7289ba2cbda125238188f34251c3ac9ae542e5164cb8"}], "language": "", "licenses": null, "cpes": ["cpe:2.3:a:python_software_foundation:python:3.11.3:*:*:*:*:*:*:*", "cpe:2.3:a:python:python:3.11.3:*:*:*:*:*:*:*"], "purl": "pkg:generic/python@3.11.3", "upstreams": null}}, {"vulnerability": {"id": "CVE-2023-41105", "dataSource": "https://nvd.nist.gov/vuln/detail/CVE-2023-41105", "namespace": "nvd:cpe", "severity": "High", "urls": ["https://github.com/python/cpython/issues/106242", "https://github.com/python/cpython/pull/107981", "https://github.com/python/cpython/pull/107982", "https://github.com/python/cpython/pull/107983", "https://mail.python.org/archives/list/security-announce%40python.org/thread/D6CDW3ZZC5D444YGL3VQUY6D4ECMCQLD/", "https://security.netapp.com/advisory/ntap-20231006-0015/", "https://github.com/python/cpython/issues/106242", "https://github.com/python/cpython/pull/107981", "https://github.com/python/cpython/pull/107982", "https://github.com/python/cpython/pull/107983", "https://mail.python.org/archives/list/security-announce%40python.org/thread/D6CDW3ZZC5D444YGL3VQUY6D4ECMCQLD/", "https://security.netapp.com/advisory/ntap-20231006-0015/"], "description": "An issue was discovered in Python 3.11 through 3.11.4. If a path containing '\\0' bytes is passed to os.path.normpath(), the path will be truncated unexpectedly at the first '\\0' byte. There are plausible cases in which an application would have rejected a filename for security reasons in Python 3.10.x or earlier, but that filename is no longer rejected in Python 3.11.x.", "cvss": [{"version": "3.1", "vector": "CVSS:3.1/AV:N/AC:L/PR:N/UI:N/S:U/C:N/I:H/A:N", "metrics": {"baseScore": 7.5, "exploitabilityScore": 3.9, "impactScore": 3.6}, "vendorMetadata": {}}], "fix": {"versions": ["3.11.5", "3.12.0rc2"], "state": "fixed"}, "advisories": null}, "relatedVulnerabilities": null, "matchDetails": [{"type": "cpe-match", "matcher": "stock-matcher", "searchedBy": {"namespace": "nvd:cpe", "cpes": ["cpe:2.3:a:python:python:3.11.3:*:*:*:*:*:*:*"], "package": {"name": "python", "version": "3.11.3"}}, "found": {"vulnerabilityID": "CVE-2023-41105", "versionConstraint": ">= 3.11.0, < 3.11.5,>= 3.12.0a1, < 3.12.0rc2 (unknown)", "cpes": ["cpe:2.3:a:python:python:*:*:*:*:*:*:*:*"]}}], "artifact": {"name": "python", "version": "3.11.3", "type": "binary", "locations": [{"path": "/usr/local/lib/libpython3.11.so.1.0", "layerID": "sha256:8e0e498514c61f26d96e7289ba2cbda125238188f34251c3ac9ae542e5164cb8"}, {"path": "/usr/local/bin/python3.11", "layerID": "sha256:8e0e498514c61f26d96e7289ba2cbda125238188f34251c3ac9ae542e5164cb8"}], "language": "", "licenses": null, "cpes": ["cpe:2.3:a:python_software_foundation:python:3.11.3:*:*:*:*:*:*:*", "cpe:2.3:a:python:python:3.11.3:*:*:*:*:*:*:*"], "purl": "pkg:generic/python@3.11.3", "upstreams": null}}, {"vulnerability": {"id": "CVE-2024-0450", "dataSource": "https://nvd.nist.gov/vuln/detail/CVE-2024-0450", "namespace": "nvd:cpe", "severity": "Medium", "urls": ["http://www.openwall.com/lists/oss-security/2024/03/20/5", "https://github.com/python/cpython/commit/30fe5d853b56138dbec62432d370a1f99409fc85", "https://github.com/python/cpython/commit/66363b9a7b9fe7c99eba3a185b74c5fdbf842eba", "https://github.com/python/cpython/commit/70497218351ba44bffc8b571201ecb5652d84675", "https://github.com/python/cpython/commit/a2c59992e9e8d35baba9695eb186ad6c6ff85c51", "https://github.com/python/cpython/commit/a956e510f6336d5ae111ba429a61c3ade30a7549", "https://github.com/python/cpython/commit/d05bac0b74153beb541b88b4fca33bf053990183", "https://github.com/python/cpython/commit/fa181fcf2156f703347b03a3b1966ce47be8ab3b", "https://github.com/python/cpython/issues/109858", "https://lists.debian.org/debian-lts-announce/2024/03/msg00024.html", "https://lists.debian.org/debian-lts-announce/2024/03/msg00025.html", "https://lists.fedoraproject.org/archives/list/package-announce@lists.fedoraproject.org/message/T3IGRX54M7RNCQOXVQO5KQKTGWCOABIM/", "https://lists.fedoraproject.org/archives/list/package-announce@lists.fedoraproject.org/message/U5VHWS52HGD743C47UMCSAK2A773M2YE/", "https://mail.python.org/archives/list/security-announce@python.org/thread/XELNUX2L3IOHBTFU7RQHCY6OUVEWZ2FG/", "https://www.bamsoftware.com/hacks/zipbomb/", "http://www.openwall.com/lists/oss-security/2024/03/20/5", "https://github.com/python/cpython/commit/30fe5d853b56138dbec62432d370a1f99409fc85", "https://github.com/python/cpython/commit/66363b9a7b9fe7c99eba3a185b74c5fdbf842eba", "https://github.com/python/cpython/commit/70497218351ba44bffc8b571201ecb5652d84675", "https://github.com/python/cpython/commit/a2c59992e9e8d35baba9695eb186ad6c6ff85c51", "https://github.com/python/cpython/commit/a956e510f6336d5ae111ba429a61c3ade30a7549", "https://github.com/python/cpython/commit/d05bac0b74153beb541b88b4fca33bf053990183", "https://github.com/python/cpython/commit/fa181fcf2156f703347b03a3b1966ce47be8ab3b", "https://github.com/python/cpython/issues/109858", "https://lists.debian.org/debian-lts-announce/2024/03/msg00024.html", "https://lists.debian.org/debian-lts-announce/2024/03/msg00025.html", "https://lists.fedoraproject.org/archives/list/package-announce@lists.fedoraproject.org/message/T3IGRX54M7RNCQOXVQO5KQKTGWCOABIM/", "https://lists.fedoraproject.org/archives/list/package-announce@lists.fedoraproject.org/message/U5VHWS52HGD743C47UMCSAK2A773M2YE/", "https://mail.python.org/archives/list/security-announce@python.org/thread/XELNUX2L3IOHBTFU7RQHCY6OUVEWZ2FG/", "https://security.netapp.com/advisory/ntap-20250411-0005/", "https://www.bamsoftware.com/hacks/zipbomb/"], "description": "An issue was found in the CPython `zipfile` module affecting versions 3.12.1, 3.11.7, 3.10.13, 3.9.18, and 3.8.18 and prior.\n\nThe zipfile module is vulnerable to \u201cquoted-overlap\u201d zip-bombs which exploit the zip format to create a zip-bomb with a high compression ratio. The fixed versions of CPython makes the zipfile module reject zip archives which overlap entries in the archive.", "cvss": [{"version": "3.1", "vector": "CVSS:3.1/AV:L/AC:L/PR:N/UI:N/S:U/C:N/I:N/A:H", "metrics": {"baseScore": 6.2, "exploitabilityScore": 2.6, "impactScore": 3.6}, "vendorMetadata": {}}], "fix": {"versions": ["3.8.19", "3.9.19", "3.10.14", "3.11.8", "3.12.2", "3.13.0a3"], "state": "fixed"}, "advisories": null}, "relatedVulnerabilities": null, "matchDetails": [{"type": "cpe-match", "matcher": "stock-matcher", "searchedBy": {"namespace": "nvd:cpe", "cpes": ["cpe:2.3:a:python:python:3.11.3:*:*:*:*:*:*:*"], "package": {"name": "python", "version": "3.11.3"}}, "found": {"vulnerabilityID": "CVE-2024-0450", "versionConstraint": "< 3.8.19,>= 3.10.0, < 3.10.14,>= 3.11.0, < 3.11.8,>= 3.12.0, < 3.12.2,>= 3.13.0a1, < 3.13.0a3,>= 3.9.0, < 3.9.19 (unknown)", "cpes": ["cpe:2.3:a:python:python:*:*:*:*:*:*:*:*"]}}], "artifact": {"name": "python", "version": "3.11.3", "type": "binary", "locations": [{"path": "/usr/local/lib/libpython3.11.so.1.0", "layerID": "sha256:8e0e498514c61f26d96e7289ba2cbda125238188f34251c3ac9ae542e5164cb8"}, {"path": "/usr/local/bin/python3.11", "layerID": "sha256:8e0e498514c61f26d96e7289ba2cbda125238188f34251c3ac9ae542e5164cb8"}], "language": "", "licenses": null, "cpes": ["cpe:2.3:a:python_software_foundation:python:3.11.3:*:*:*:*:*:*:*", "cpe:2.3:a:python:python:3.11.3:*:*:*:*:*:*:*"], "purl": "pkg:generic/python@3.11.3", "upstreams": null}}, {"vulnerability": {"id": "CVE-2025-4330", "dataSource": "https://nvd.nist.gov/vuln/detail/CVE-2025-4330", "namespace": "nvd:cpe", "severity": "High", "urls": ["https://gist.github.com/sethmlarson/52398e33eff261329a0180ac1d54f42f", "https://github.com/python/cpython/commit/19de092debb3d7e832e5672cc2f7b788d35951da", "https://github.com/python/cpython/commit/28463dba112af719df1e8b0391c46787ad756dd9", "https://github.com/python/cpython/commit/3612d8f51741b11f36f8fb0494d79086bac9390a", "https://github.com/python/cpython/commit/4633f3f497b1ff70e4a35b6fe2c907cbe2d4cb2e", "https://github.com/python/cpython/commit/9c1110ef6652687d7c55f590f909720eddde965a", "https://github.com/python/cpython/commit/9e0ac76d96cf80b49055f6d6b9a6763fb9215c2a", "https://github.com/python/cpython/commit/aa9eb5f757ceff461e6e996f12c89e5d9b583b01", "https://github.com/python/cpython/commit/dd8f187d0746da151e0025c51680979ac5b4cfb1", "https://github.com/python/cpython/issues/135034", "https://github.com/python/cpython/pull/135037", "https://mail.python.org/archives/list/security-announce@python.org/thread/MAXIJJCUUMCL7ATZNDVEGGHUMQMUUKLG/"], "description": "Allows the extraction filter to be ignored, allowing symlink targets to point outside the destination directory, and the modification of some file metadata.\n\n\nYou are affected by this vulnerability if using the tarfile\u00a0module to extract untrusted tar archives using TarFile.extractall()\u00a0or TarFile.extract()\u00a0using the filter=\u00a0parameter with a value of \"data\"\u00a0or \"tar\". See the tarfile  extraction filters documentation https://docs.python.org/3/library/tarfile.html#tarfile-extraction-filter \u00a0for more information.\n\nNote that for Python 3.14 or later the default value of filter=\u00a0changed from \"no filtering\" to `\"data\", so if you are relying on this new default behavior then your usage is also affected.\n\nNote that none of these vulnerabilities significantly affect the installation of source distributions which are tar archives as source distributions already allow arbitrary code execution during the build process. However when evaluating source distributions it's important to avoid installing source distributions with suspicious links.", "cvss": [{"version": "3.1", "vector": "CVSS:3.1/AV:N/AC:L/PR:N/UI:N/S:U/C:N/I:H/A:N", "metrics": {"baseScore": 7.5, "exploitabilityScore": 3.9, "impactScore": 3.6}, "vendorMetadata": {}}], "fix": {"versions": ["3.9.23", "3.10.18", "3.11.13", "3.12.11", "3.13.4", "3.14.0b3"], "state": "fixed"}, "advisories": null}, "relatedVulnerabilities": null, "matchDetails": [{"type": "cpe-match", "matcher": "stock-matcher", "searchedBy": {"namespace": "nvd:cpe", "cpes": ["cpe:2.3:a:python:python:3.11.3:*:*:*:*:*:*:*"], "package": {"name": "python", "version": "3.11.3"}}, "found": {"vulnerabilityID": "CVE-2025-4330", "versionConstraint": "< 3.9.23,>= 3.10.0, < 3.10.18,>= 3.11.0, < 3.11.13,>= 3.12.0, < 3.12.11,>= 3.13.0, < 3.13.4,>= 3.14.0a1, < 3.14.0b3 (unknown)", "cpes": ["cpe:2.3:a:python:python:*:*:*:*:*:*:*:*"]}}], "artifact": {"name": "python", "version": "3.11.3", "type": "binary", "locations": [{"path": "/usr/local/lib/libpython3.11.so.1.0", "layerID": "sha256:8e0e498514c61f26d96e7289ba2cbda125238188f34251c3ac9ae542e5164cb8"}, {"path": "/usr/local/bin/python3.11", "layerID": "sha256:8e0e498514c61f26d96e7289ba2cbda125238188f34251c3ac9ae542e5164cb8"}], "language": "", "licenses": null, "cpes": ["cpe:2.3:a:python_software_foundation:python:3.11.3:*:*:*:*:*:*:*", "cpe:2.3:a:python:python:3.11.3:*:*:*:*:*:*:*"], "purl": "pkg:generic/python@3.11.3", "upstreams": null}}, {"vulnerability": {"id": "CVE-2024-6923", "dataSource": "https://nvd.nist.gov/vuln/detail/CVE-2024-6923", "namespace": "nvd:cpe", "severity": "Medium", "urls": ["https://github.com/python/cpython/commit/06f28dc236708f72871c64d4bc4b4ea144c50147", "https://github.com/python/cpython/commit/097633981879b3c9de9a1dd120d3aa585ecc2384", "https://github.com/python/cpython/commit/4766d1200fdf8b6728137aa2927a297e224d5fa7", "https://github.com/python/cpython/commit/4aaa4259b5a6e664b7316a4d60bdec7ee0f124d0", "https://github.com/python/cpython/commit/b158a76ce094897c870fb6b3de62887b7ccc33f1", "https://github.com/python/cpython/commit/f7be505d137a22528cb0fc004422c0081d5d90e6", "https://github.com/python/cpython/commit/f7c0f09e69e950cf3c5ada9dbde93898eb975533", "https://github.com/python/cpython/issues/121650", "https://github.com/python/cpython/pull/122233", "https://mail.python.org/archives/list/security-announce@python.org/thread/QH3BUOE2DYQBWP7NAQ7UNHPPOELKISRW/", "http://www.openwall.com/lists/oss-security/2024/08/01/3", "http://www.openwall.com/lists/oss-security/2024/08/02/2", "https://lists.debian.org/debian-lts-announce/2025/01/msg00005.html", "https://security.netapp.com/advisory/ntap-20240926-0003/"], "description": "There is a MEDIUM severity vulnerability affecting CPython.\n\nThe \nemail module didn\u2019t properly quote newlines for email headers when \nserializing an email message allowing for header injection when an email\n is serialized.", "cvss": [{"version": "3.1", "vector": "CVSS:3.1/AV:N/AC:L/PR:L/UI:R/S:U/C:L/I:L/A:L", "metrics": {"baseScore": 5.5, "exploitabilityScore": 2.1, "impactScore": 3.4}, "vendorMetadata": {}}], "fix": {"versions": ["3.8.20", "3.9.20", "3.10.15", "3.11.10", "3.12.5", "3.13.0rc2"], "state": "fixed"}, "advisories": null}, "relatedVulnerabilities": null, "matchDetails": [{"type": "cpe-match", "matcher": "stock-matcher", "searchedBy": {"namespace": "nvd:cpe", "cpes": ["cpe:2.3:a:python:python:3.11.3:*:*:*:*:*:*:*"], "package": {"name": "python", "version": "3.11.3"}}, "found": {"vulnerabilityID": "CVE-2024-6923", "versionConstraint": "< 3.8.20,>= 3.10.0, < 3.10.15,>= 3.11.0, < 3.11.10,>= 3.12.0, < 3.12.5,>= 3.13.0a1, < 3.13.0rc2,>= 3.9.0, < 3.9.20 (unknown)", "cpes": ["cpe:2.3:a:python:python:*:*:*:*:*:*:*:*"]}}], "artifact": {"name": "python", "version": "3.11.3", "type": "binary", "locations": [{"path": "/usr/local/lib/libpython3.11.so.1.0", "layerID": "sha256:8e0e498514c61f26d96e7289ba2cbda125238188f34251c3ac9ae542e5164cb8"}, {"path": "/usr/local/bin/python3.11", "layerID": "sha256:8e0e498514c61f26d96e7289ba2cbda125238188f34251c3ac9ae542e5164cb8"}], "language": "", "licenses": null, "cpes": ["cpe:2.3:a:python_software_foundation:python:3.11.3:*:*:*:*:*:*:*", "cpe:2.3:a:python:python:3.11.3:*:*:*:*:*:*:*"], "purl": "pkg:generic/python@3.11.3", "upstreams": null}}, {"vulnerability": {"id": "CVE-2025-4138", "dataSource": "https://nvd.nist.gov/vuln/detail/CVE-2025-4138", "namespace": "nvd:cpe", "severity": "High", "urls": ["https://gist.github.com/sethmlarson/52398e33eff261329a0180ac1d54f42f", "https://github.com/python/cpython/commit/19de092debb3d7e832e5672cc2f7b788d35951da", "https://github.com/python/cpython/commit/28463dba112af719df1e8b0391c46787ad756dd9", "https://github.com/python/cpython/commit/3612d8f51741b11f36f8fb0494d79086bac9390a", "https://github.com/python/cpython/commit/4633f3f497b1ff70e4a35b6fe2c907cbe2d4cb2e", "https://github.com/python/cpython/commit/9c1110ef6652687d7c55f590f909720eddde965a", "https://github.com/python/cpython/commit/9e0ac76d96cf80b49055f6d6b9a6763fb9215c2a", "https://github.com/python/cpython/commit/aa9eb5f757ceff461e6e996f12c89e5d9b583b01", "https://github.com/python/cpython/commit/dd8f187d0746da151e0025c51680979ac5b4cfb1", "https://github.com/python/cpython/issues/135034", "https://github.com/python/cpython/pull/135037", "https://mail.python.org/archives/list/security-announce@python.org/thread/MAXIJJCUUMCL7ATZNDVEGGHUMQMUUKLG/"], "description": "Allows the extraction filter to be ignored, allowing symlink targets to point outside the destination directory, and the modification of some file metadata.\n\n\nYou are affected by this vulnerability if using the tarfile\u00a0module to extract untrusted tar archives using TarFile.extractall()\u00a0or TarFile.extract()\u00a0using the filter=\u00a0parameter with a value of \"data\"\u00a0or \"tar\". See the tarfile  extraction filters documentation https://docs.python.org/3/library/tarfile.html#tarfile-extraction-filter \u00a0for more information.\n\nNote that for Python 3.14 or later the default value of filter=\u00a0changed from \"no filtering\" to `\"data\", so if you are relying on this new default behavior then your usage is also affected.\n\nNote that none of these vulnerabilities significantly affect the installation of source distributions which are tar archives as source distributions already allow arbitrary code execution during the build process. However when evaluating source distributions it's important to avoid installing source distributions with suspicious links.", "cvss": [{"version": "3.1", "vector": "CVSS:3.1/AV:N/AC:L/PR:N/UI:N/S:U/C:H/I:N/A:N", "metrics": {"baseScore": 7.5, "exploitabilityScore": 3.9, "impactScore": 3.6}, "vendorMetadata": {}}], "fix": {"versions": ["3.9.23", "3.10.18", "3.11.13", "3.12.11", "3.13.4", "3.14.0b3"], "state": "fixed"}, "advisories": null}, "relatedVulnerabilities": null, "matchDetails": [{"type": "cpe-match", "matcher": "stock-matcher", "searchedBy": {"namespace": "nvd:cpe", "cpes": ["cpe:2.3:a:python:python:3.11.3:*:*:*:*:*:*:*"], "package": {"name": "python", "version": "3.11.3"}}, "found": {"vulnerabilityID": "CVE-2025-4138", "versionConstraint": "< 3.9.23,>= 3.10.0, < 3.10.18,>= 3.11.0, < 3.11.13,>= 3.12.0, < 3.12.11,>= 3.13.0, < 3.13.4,>= 3.14.0a1, < 3.14.0b3 (unknown)", "cpes": ["cpe:2.3:a:python:python:*:*:*:*:*:*:*:*"]}}], "artifact": {"name": "python", "version": "3.11.3", "type": "binary", "locations": [{"path": "/usr/local/lib/libpython3.11.so.1.0", "layerID": "sha256:8e0e498514c61f26d96e7289ba2cbda125238188f34251c3ac9ae542e5164cb8"}, {"path": "/usr/local/bin/python3.11", "layerID": "sha256:8e0e498514c61f26d96e7289ba2cbda125238188f34251c3ac9ae542e5164cb8"}], "language": "", "licenses": null, "cpes": ["cpe:2.3:a:python_software_foundation:python:3.11.3:*:*:*:*:*:*:*", "cpe:2.3:a:python:python:3.11.3:*:*:*:*:*:*:*"], "purl": "pkg:generic/python@3.11.3", "upstreams": null}}, {"vulnerability": {"id": "CVE-2024-8088", "dataSource": "https://nvd.nist.gov/vuln/detail/CVE-2024-8088", "namespace": "nvd:cpe", "severity": "High", "urls": ["https://github.com/python/cpython/commit/0aa1ee22ab6e204e9d3d0e9dd63ea648ed691ef1", "https://github.com/python/cpython/commit/2231286d78d328c2f575e0b05b16fe447d1656d6", "https://github.com/python/cpython/commit/795f2597a4be988e2bb19b69ff9958e981cb894e", "https://github.com/python/cpython/commit/7bc367e464ce50b956dd232c1dfa1cad4e7fb814", "https://github.com/python/cpython/commit/7e8883a3f04d308302361aeffc73e0e9837f19d4", "https://github.com/python/cpython/commit/8c7348939d8a3ecd79d630075f6be1b0c5b41f64", "https://github.com/python/cpython/commit/95b073bddefa6243effa08e131e297c0383e7f6a", "https://github.com/python/cpython/commit/962055268ed4f2ca1d717bfc8b6385de50a23ab7", "https://github.com/python/cpython/commit/dcc5182f27c1500006a1ef78e10613bb45788dea", "https://github.com/python/cpython/commit/e0264a61119d551658d9445af38323ba94fc16db", "https://github.com/python/cpython/commit/fc0b8259e693caa8400fa8b6ac1e494e47ea7798", "https://github.com/python/cpython/issues/122905", "https://github.com/python/cpython/issues/123270", "https://github.com/python/cpython/pull/122906", "https://mail.python.org/archives/list/security-announce@python.org/thread/GNFCKVI4TCATKQLALJ5SN4L4CSPSMILU/", "http://www.openwall.com/lists/oss-security/2024/08/22/1", "http://www.openwall.com/lists/oss-security/2024/08/22/4", "http://www.openwall.com/lists/oss-security/2024/08/23/1", "http://www.openwall.com/lists/oss-security/2024/08/23/2", "https://security.netapp.com/advisory/ntap-20241011-0010/"], "description": "There is a HIGH severity vulnerability affecting the CPython \"zipfile\"\nmodule affecting \"zipfile.Path\". Note that the more common API \"zipfile.ZipFile\" class is unaffected.\n\n\n\n\n\nWhen iterating over names of entries in a zip archive (for example, methods\nof \"zipfile.Path\" like \"namelist()\", \"iterdir()\", etc)\nthe process can be put into an infinite loop with a maliciously crafted\nzip archive. This defect applies when reading only metadata or extracting\nthe contents of the zip archive. Programs that are not handling\nuser-controlled zip archives are not affected.", "cvss": [{"version": "4.0", "vector": "CVSS:4.0/AV:N/AC:L/AT:N/PR:N/UI:N/VC:N/VI:N/VA:H/SC:N/SI:N/SA:N/E:X/CR:X/IR:X/AR:X/MAV:X/MAC:X/MAT:X/MPR:X/MUI:X/MVC:X/MVI:X/MVA:X/MSC:X/MSI:X/MSA:X/S:N/AU:N/R:U/V:X/RE:L/U:X", "metrics": {"baseScore": 8.7}, "vendorMetadata": {}}], "fix": {"versions": ["3.8.20", "3.9.20", "3.10.15", "3.11.10", "3.12.6", "3.13.0rc2"], "state": "fixed"}, "advisories": null}, "relatedVulnerabilities": null, "matchDetails": [{"type": "cpe-match", "matcher": "stock-matcher", "searchedBy": {"namespace": "nvd:cpe", "cpes": ["cpe:2.3:a:python:python:3.11.3:*:*:*:*:*:*:*"], "package": {"name": "python", "version": "3.11.3"}}, "found": {"vulnerabilityID": "CVE-2024-8088", "versionConstraint": "< 3.8.20,>= 3.10.0, < 3.10.15,>= 3.11.0, < 3.11.10,>= 3.12.0, < 3.12.6,>= 3.13.0a1, < 3.13.0rc2,>= 3.9.0, < 3.9.20 (unknown)", "cpes": ["cpe:2.3:a:python:python:*:*:*:*:*:*:*:*"]}}], "artifact": {"name": "python", "version": "3.11.3", "type": "binary", "locations": [{"path": "/usr/local/lib/libpython3.11.so.1.0", "layerID": "sha256:8e0e498514c61f26d96e7289ba2cbda125238188f34251c3ac9ae542e5164cb8"}, {"path": "/usr/local/bin/python3.11", "layerID": "sha256:8e0e498514c61f26d96e7289ba2cbda125238188f34251c3ac9ae542e5164cb8"}], "language": "", "licenses": null, "cpes": ["cpe:2.3:a:python_software_foundation:python:3.11.3:*:*:*:*:*:*:*", "cpe:2.3:a:python:python:3.11.3:*:*:*:*:*:*:*"], "purl": "pkg:generic/python@3.11.3", "upstreams": null}}, {"vulnerability": {"id": "CVE-2025-8194", "dataSource": "https://nvd.nist.gov/vuln/detail/CVE-2025-8194", "namespace": "nvd:cpe", "severity": "High", "urls": ["https://gist.github.com/sethmlarson/1716ac5b82b73dbcbf23ad2eff8b33e1", "https://github.com/python/cpython/commit/7040aa54f14676938970e10c5f74ea93cd56aa38", "https://github.com/python/cpython/commit/c9d9f78feb1467e73fd29356c040bde1c104f29f", "https://github.com/python/cpython/commit/cdae923ffe187d6ef916c0f665a31249619193fe", "https://github.com/python/cpython/commit/fbc2a0ca9ac8aff6887f8ddf79b87b4510277227", "https://github.com/python/cpython/issues/130577", "https://github.com/python/cpython/pull/137027", "https://mail.python.org/archives/list/security-announce@python.org/thread/ZULLF3IZ726XP5EY7XJ7YIN3K5MDYR2D/"], "description": "There is a defect in the CPython \u201ctarfile\u201d module affecting the \u201cTarFile\u201d extraction and entry enumeration APIs. The tar implementation would process tar archives with negative offsets without error, resulting in an infinite loop and deadlock during the parsing of maliciously crafted tar archives. \n\nThis vulnerability can be mitigated by including the following patch after importing the \u201ctarfile\u201d module:\u00a0 https://gist.github.com/sethmlarson/1716ac5b82b73dbcbf23ad2eff8b33e1", "cvss": [{"version": "3.1", "vector": "CVSS:3.1/AV:N/AC:L/PR:N/UI:N/S:U/C:N/I:N/A:H", "metrics": {"baseScore": 7.5, "exploitabilityScore": 3.9, "impactScore": 3.6}, "vendorMetadata": {}}], "fix": {"versions": ["3.13.6", "3.14.0rc2"], "state": "fixed"}, "advisories": null}, "relatedVulnerabilities": null, "matchDetails": [{"type": "cpe-match", "matcher": "stock-matcher", "searchedBy": {"namespace": "nvd:cpe", "cpes": ["cpe:2.3:a:python:python:3.11.3:*:*:*:*:*:*:*"], "package": {"name": "python", "version": "3.11.3"}}, "found": {"vulnerabilityID": "CVE-2025-8194", "versionConstraint": "< 3.13.6,>= 3.14.0a1, < 3.14.0rc2 (unknown)", "cpes": ["cpe:2.3:a:python:python:*:*:*:*:*:*:*:*"]}}], "artifact": {"name": "python", "version": "3.11.3", "type": "binary", "locations": [{"path": "/usr/local/lib/libpython3.11.so.1.0", "layerID": "sha256:8e0e498514c61f26d96e7289ba2cbda125238188f34251c3ac9ae542e5164cb8"}, {"path": "/usr/local/bin/python3.11", "layerID": "sha256:8e0e498514c61f26d96e7289ba2cbda125238188f34251c3ac9ae542e5164cb8"}], "language": "", "licenses": null, "cpes": ["cpe:2.3:a:python_software_foundation:python:3.11.3:*:*:*:*:*:*:*", "cpe:2.3:a:python:python:3.11.3:*:*:*:*:*:*:*"], "purl": "pkg:generic/python@3.11.3", "upstreams": null}}, {"vulnerability": {"id": "CVE-2023-6597", "dataSource": "https://nvd.nist.gov/vuln/detail/CVE-2023-6597", "namespace": "nvd:cpe", "severity": "High", "urls": ["http://www.openwall.com/lists/oss-security/2024/03/20/5", "https://github.com/python/cpython/commit/02a9259c717738dfe6b463c44d7e17f2b6d2cb3a", "https://github.com/python/cpython/commit/5585334d772b253a01a6730e8202ffb1607c3d25", "https://github.com/python/cpython/commit/6ceb8aeda504b079fef7a57b8d81472f15cdd9a5", "https://github.com/python/cpython/commit/81c16cd94ec38d61aa478b9a452436dc3b1b524d", "https://github.com/python/cpython/commit/8eaeefe49d179ca4908d052745e3bb8b6f238f82", "https://github.com/python/cpython/commit/d54e22a669ae6e987199bb5d2c69bb5a46b0083b", "https://github.com/python/cpython/issues/91133", "https://lists.debian.org/debian-lts-announce/2024/03/msg00025.html", "https://lists.fedoraproject.org/archives/list/package-announce@lists.fedoraproject.org/message/T3IGRX54M7RNCQOXVQO5KQKTGWCOABIM/", "https://lists.fedoraproject.org/archives/list/package-announce@lists.fedoraproject.org/message/U5VHWS52HGD743C47UMCSAK2A773M2YE/", "https://mail.python.org/archives/list/security-announce@python.org/thread/Q5C6ATFC67K53XFV4KE45325S7NS62LD/", "http://www.openwall.com/lists/oss-security/2024/03/20/5", "https://github.com/python/cpython/commit/02a9259c717738dfe6b463c44d7e17f2b6d2cb3a", "https://github.com/python/cpython/commit/5585334d772b253a01a6730e8202ffb1607c3d25", "https://github.com/python/cpython/commit/6ceb8aeda504b079fef7a57b8d81472f15cdd9a5", "https://github.com/python/cpython/commit/81c16cd94ec38d61aa478b9a452436dc3b1b524d", "https://github.com/python/cpython/commit/8eaeefe49d179ca4908d052745e3bb8b6f238f82", "https://github.com/python/cpython/commit/d54e22a669ae6e987199bb5d2c69bb5a46b0083b", "https://github.com/python/cpython/issues/91133", "https://lists.debian.org/debian-lts-announce/2024/03/msg00025.html", "https://lists.fedoraproject.org/archives/list/package-announce@lists.fedoraproject.org/message/T3IGRX54M7RNCQOXVQO5KQKTGWCOABIM/", "https://lists.fedoraproject.org/archives/list/package-announce@lists.fedoraproject.org/message/U5VHWS52HGD743C47UMCSAK2A773M2YE/", "https://mail.python.org/archives/list/security-announce@python.org/thread/Q5C6ATFC67K53XFV4KE45325S7NS62LD/"], "description": "An issue was found in the CPython `tempfile.TemporaryDirectory` class affecting versions 3.12.1, 3.11.7, 3.10.13, 3.9.18, and 3.8.18 and prior.\n\nThe tempfile.TemporaryDirectory class would dereference symlinks during cleanup of permissions-related errors. This means users which can run privileged programs are potentially able to modify permissions of files referenced by symlinks in some circumstances.", "cvss": [{"version": "3.1", "vector": "CVSS:3.1/AV:L/AC:H/PR:N/UI:N/S:C/C:H/I:H/A:N", "metrics": {"baseScore": 7.8, "exploitabilityScore": 1.5, "impactScore": 5.8}, "vendorMetadata": {}}], "fix": {"versions": ["3.8.19", "3.9.19", "3.10.14", "3.11.8", "3.12.1", "3.13.0a3"], "state": "fixed"}, "advisories": null}, "relatedVulnerabilities": null, "matchDetails": [{"type": "cpe-match", "matcher": "stock-matcher", "searchedBy": {"namespace": "nvd:cpe", "cpes": ["cpe:2.3:a:python:python:3.11.3:*:*:*:*:*:*:*"], "package": {"name": "python", "version": "3.11.3"}}, "found": {"vulnerabilityID": "CVE-2023-6597", "versionConstraint": "< 3.8.19,>= 3.10.0, < 3.10.14,>= 3.11.0, < 3.11.8,>= 3.12.0, < 3.12.1,>= 3.13.0a1, < 3.13.0a3,>= 3.9.0, < 3.9.19 (unknown)", "cpes": ["cpe:2.3:a:python:python:*:*:*:*:*:*:*:*"]}}], "artifact": {"name": "python", "version": "3.11.3", "type": "binary", "locations": [{"path": "/usr/local/lib/libpython3.11.so.1.0", "layerID": "sha256:8e0e498514c61f26d96e7289ba2cbda125238188f34251c3ac9ae542e5164cb8"}, {"path": "/usr/local/bin/python3.11", "layerID": "sha256:8e0e498514c61f26d96e7289ba2cbda125238188f34251c3ac9ae542e5164cb8"}], "language": "", "licenses": null, "cpes": ["cpe:2.3:a:python_software_foundation:python:3.11.3:*:*:*:*:*:*:*", "cpe:2.3:a:python:python:3.11.3:*:*:*:*:*:*:*"], "purl": "pkg:generic/python@3.11.3", "upstreams": null}}, {"vulnerability": {"id": "CVE-2023-27043", "dataSource": "https://nvd.nist.gov/vuln/detail/CVE-2023-27043", "namespace": "nvd:cpe", "severity": "Medium", "urls": ["http://python.org", "https://github.com/python/cpython/issues/102988", "https://lists.fedoraproject.org/archives/list/package-announce%40lists.fedoraproject.org/message/4ZAEFSFZDNBNJPNOUTLG5COISGQDLMGV/", "https://lists.fedoraproject.org/archives/list/package-announce%40lists.fedoraproject.org/message/75DTHSTNOFFNAWHXKMDXS7EJWC6W2FUC/", "https://lists.fedoraproject.org/archives/list/package-announce%40lists.fedoraproject.org/message/ARI7VDSNTQVXRQFM6IK5GSSLEIYV4VZH/", "https://lists.fedoraproject.org/archives/list/package-announce%40lists.fedoraproject.org/message/BQAKLUJMHFGVBRDPEY57BJGNCE5UUPHW/", "https://lists.fedoraproject.org/archives/list/package-announce%40lists.fedoraproject.org/message/HXYVPEZUA3465AEFX5JVFVP7KIFZMF3N/", "https://lists.fedoraproject.org/archives/list/package-announce%40lists.fedoraproject.org/message/N6M5I6OQHJABNEYY555HUMMKX3Y4P25Z/", "https://lists.fedoraproject.org/archives/list/package-announce%40lists.fedoraproject.org/message/NEUNZSZ3CVSM2QWVYH3N2XGOCDWNYUA3/", "https://lists.fedoraproject.org/archives/list/package-announce%40lists.fedoraproject.org/message/ORLXS5YTKN65E2Q2NWKXMFS5FWQHRNZW/", "https://lists.fedoraproject.org/archives/list/package-announce%40lists.fedoraproject.org/message/P2MAICLFDDO3QVNHTZ2OCERZQ34R2PIC/", "https://lists.fedoraproject.org/archives/list/package-announce%40lists.fedoraproject.org/message/P2W2BZQIHMCKRI5FNBJERFYMS5PK6TAH/", "https://lists.fedoraproject.org/archives/list/package-announce%40lists.fedoraproject.org/message/PHVGRKQAGANCSGFI3QMYOCIMS4IFOZA5/", "https://lists.fedoraproject.org/archives/list/package-announce%40lists.fedoraproject.org/message/PU6Y2S5CBN5BWCBDAJFTGIBZLK3S2G3J/", "https://lists.fedoraproject.org/archives/list/package-announce%40lists.fedoraproject.org/message/QDRDDPDN3VFIYXJIYEABY6USX5EU66AG/", "https://lists.fedoraproject.org/archives/list/package-announce%40lists.fedoraproject.org/message/RDDC2VOX7OQC6OHMYTVD4HLFZIV6PYBC/", "https://lists.fedoraproject.org/archives/list/package-announce%40lists.fedoraproject.org/message/SINP4OVYNB2AGDYI2GS37EMW3H3F7XPZ/", "https://lists.fedoraproject.org/archives/list/package-announce%40lists.fedoraproject.org/message/SOX7BCN6YL7B3RFPEEXPIU5CMTEHJOKR/", "https://lists.fedoraproject.org/archives/list/package-announce%40lists.fedoraproject.org/message/VZXC32CJ7TWDPJO6GY2XIQRO7JZX5FLP/", "https://lists.fedoraproject.org/archives/list/package-announce%40lists.fedoraproject.org/message/XWMBD4LNHWEXRI6YVFWJMTJQUL5WOFTS/", "https://lists.fedoraproject.org/archives/list/package-announce%40lists.fedoraproject.org/message/YQVY5C5REXWJIORJIL2FIL3ALOEJEF72/", "https://python-security.readthedocs.io/vuln/email-parseaddr-realname.html", "https://security.netapp.com/advisory/ntap-20230601-0003/", "http://python.org", "https://github.com/python/cpython/issues/102988", "https://lists.fedoraproject.org/archives/list/package-announce%40lists.fedoraproject.org/message/4ZAEFSFZDNBNJPNOUTLG5COISGQDLMGV/", "https://lists.fedoraproject.org/archives/list/package-announce%40lists.fedoraproject.org/message/75DTHSTNOFFNAWHXKMDXS7EJWC6W2FUC/", "https://lists.fedoraproject.org/archives/list/package-announce%40lists.fedoraproject.org/message/ARI7VDSNTQVXRQFM6IK5GSSLEIYV4VZH/", "https://lists.fedoraproject.org/archives/list/package-announce%40lists.fedoraproject.org/message/BQAKLUJMHFGVBRDPEY57BJGNCE5UUPHW/", "https://lists.fedoraproject.org/archives/list/package-announce%40lists.fedoraproject.org/message/HXYVPEZUA3465AEFX5JVFVP7KIFZMF3N/", "https://lists.fedoraproject.org/archives/list/package-announce%40lists.fedoraproject.org/message/N6M5I6OQHJABNEYY555HUMMKX3Y4P25Z/", "https://lists.fedoraproject.org/archives/list/package-announce%40lists.fedoraproject.org/message/NEUNZSZ3CVSM2QWVYH3N2XGOCDWNYUA3/", "https://lists.fedoraproject.org/archives/list/package-announce%40lists.fedoraproject.org/message/ORLXS5YTKN65E2Q2NWKXMFS5FWQHRNZW/", "https://lists.fedoraproject.org/archives/list/package-announce%40lists.fedoraproject.org/message/P2MAICLFDDO3QVNHTZ2OCERZQ34R2PIC/", "https://lists.fedoraproject.org/archives/list/package-announce%40lists.fedoraproject.org/message/P2W2BZQIHMCKRI5FNBJERFYMS5PK6TAH/", "https://lists.fedoraproject.org/archives/list/package-announce%40lists.fedoraproject.org/message/PHVGRKQAGANCSGFI3QMYOCIMS4IFOZA5/", "https://lists.fedoraproject.org/archives/list/package-announce%40lists.fedoraproject.org/message/PU6Y2S5CBN5BWCBDAJFTGIBZLK3S2G3J/", "https://lists.fedoraproject.org/archives/list/package-announce%40lists.fedoraproject.org/message/QDRDDPDN3VFIYXJIYEABY6USX5EU66AG/", "https://lists.fedoraproject.org/archives/list/package-announce%40lists.fedoraproject.org/message/RDDC2VOX7OQC6OHMYTVD4HLFZIV6PYBC/", "https://lists.fedoraproject.org/archives/list/package-announce%40lists.fedoraproject.org/message/SINP4OVYNB2AGDYI2GS37EMW3H3F7XPZ/", "https://lists.fedoraproject.org/archives/list/package-announce%40lists.fedoraproject.org/message/SOX7BCN6YL7B3RFPEEXPIU5CMTEHJOKR/", "https://lists.fedoraproject.org/archives/list/package-announce%40lists.fedoraproject.org/message/VZXC32CJ7TWDPJO6GY2XIQRO7JZX5FLP/", "https://lists.fedoraproject.org/archives/list/package-announce%40lists.fedoraproject.org/message/XWMBD4LNHWEXRI6YVFWJMTJQUL5WOFTS/", "https://lists.fedoraproject.org/archives/list/package-announce%40lists.fedoraproject.org/message/YQVY5C5REXWJIORJIL2FIL3ALOEJEF72/", "https://lists.fedoraproject.org/archives/list/package-announce@lists.fedoraproject.org/message/4ZAEFSFZDNBNJPNOUTLG5COISGQDLMGV/", "https://lists.fedoraproject.org/archives/list/package-announce@lists.fedoraproject.org/message/75DTHSTNOFFNAWHXKMDXS7EJWC6W2FUC/", "https://lists.fedoraproject.org/archives/list/package-announce@lists.fedoraproject.org/message/ARI7VDSNTQVXRQFM6IK5GSSLEIYV4VZH/", "https://lists.fedoraproject.org/archives/list/package-announce@lists.fedoraproject.org/message/BQAKLUJMHFGVBRDPEY57BJGNCE5UUPHW/", "https://lists.fedoraproject.org/archives/list/package-announce@lists.fedoraproject.org/message/HXYVPEZUA3465AEFX5JVFVP7KIFZMF3N/", "https://lists.fedoraproject.org/archives/list/package-announce@lists.fedoraproject.org/message/N6M5I6OQHJABNEYY555HUMMKX3Y4P25Z/", "https://lists.fedoraproject.org/archives/list/package-announce@lists.fedoraproject.org/message/NEUNZSZ3CVSM2QWVYH3N2XGOCDWNYUA3/", "https://lists.fedoraproject.org/archives/list/package-announce@lists.fedoraproject.org/message/ORLXS5YTKN65E2Q2NWKXMFS5FWQHRNZW/", "https://lists.fedoraproject.org/archives/list/package-announce@lists.fedoraproject.org/message/P2MAICLFDDO3QVNHTZ2OCERZQ34R2PIC/", "https://lists.fedoraproject.org/archives/list/package-announce@lists.fedoraproject.org/message/P2W2BZQIHMCKRI5FNBJERFYMS5PK6TAH/", "https://lists.fedoraproject.org/archives/list/package-announce@lists.fedoraproject.org/message/PHVGRKQAGANCSGFI3QMYOCIMS4IFOZA5/", "https://lists.fedoraproject.org/archives/list/package-announce@lists.fedoraproject.org/message/PU6Y2S5CBN5BWCBDAJFTGIBZLK3S2G3J/", "https://lists.fedoraproject.org/archives/list/package-announce@lists.fedoraproject.org/message/QDRDDPDN3VFIYXJIYEABY6USX5EU66AG/", "https://lists.fedoraproject.org/archives/list/package-announce@lists.fedoraproject.org/message/RDDC2VOX7OQC6OHMYTVD4HLFZIV6PYBC/", "https://lists.fedoraproject.org/archives/list/package-announce@lists.fedoraproject.org/message/SINP4OVYNB2AGDYI2GS37EMW3H3F7XPZ/", "https://lists.fedoraproject.org/archives/list/package-announce@lists.fedoraproject.org/message/VZXC32CJ7TWDPJO6GY2XIQRO7JZX5FLP/", "https://lists.fedoraproject.org/archives/list/package-announce@lists.fedoraproject.org/message/XWMBD4LNHWEXRI6YVFWJMTJQUL5WOFTS/", "https://lists.fedoraproject.org/archives/list/package-announce@lists.fedoraproject.org/message/YQVY5C5REXWJIORJIL2FIL3ALOEJEF72/", "https://python-security.readthedocs.io/vuln/email-parseaddr-realname.html", "https://security.netapp.com/advisory/ntap-20230601-0003/"], "description": "The email module of Python through 3.11.3 incorrectly parses e-mail addresses that contain a special character. The wrong portion of an RFC2822 header is identified as the value of the addr-spec. In some applications, an attacker can bypass a protection mechanism in which application access is granted only after verifying receipt of e-mail to a specific domain (e.g., only @company.example.com addresses may be used for signup). This occurs in email/_parseaddr.py in recent versions of Python.", "cvss": [{"version": "3.1", "vector": "CVSS:3.1/AV:N/AC:L/PR:N/UI:N/S:U/C:N/I:L/A:N", "metrics": {"baseScore": 5.3, "exploitabilityScore": 3.9, "impactScore": 1.5}, "vendorMetadata": {}}], "fix": {"versions": ["3.8.20", "3.9.20", "3.10.15", "3.11.10", "3.12.6", "3.13.0a1"], "state": "fixed"}, "advisories": null}, "relatedVulnerabilities": null, "matchDetails": [{"type": "cpe-match", "matcher": "stock-matcher", "searchedBy": {"namespace": "nvd:cpe", "cpes": ["cpe:2.3:a:python:python:3.11.3:*:*:*:*:*:*:*"], "package": {"name": "python", "version": "3.11.3"}}, "found": {"vulnerabilityID": "CVE-2023-27043", "versionConstraint": "< 3.8.20,>= 3.10.0a0, < 3.10.15,>= 3.11.0a0, < 3.11.10,>= 3.12.0a0, < 3.12.6,>= 3.13.0a0, < 3.13.0a1,>= 3.9.0a0, < 3.9.20 (unknown)", "cpes": ["cpe:2.3:a:python:python:*:*:*:*:*:*:*:*"]}}], "artifact": {"name": "python", "version": "3.11.3", "type": "binary", "locations": [{"path": "/usr/local/lib/libpython3.11.so.1.0", "layerID": "sha256:8e0e498514c61f26d96e7289ba2cbda125238188f34251c3ac9ae542e5164cb8"}, {"path": "/usr/local/bin/python3.11", "layerID": "sha256:8e0e498514c61f26d96e7289ba2cbda125238188f34251c3ac9ae542e5164cb8"}], "language": "", "licenses": null, "cpes": ["cpe:2.3:a:python_software_foundation:python:3.11.3:*:*:*:*:*:*:*", "cpe:2.3:a:python:python:3.11.3:*:*:*:*:*:*:*"], "purl": "pkg:generic/python@3.11.3", "upstreams": null}}, {"vulnerability": {"id": "CVE-2023-36632", "dataSource": "https://nvd.nist.gov/vuln/detail/CVE-2023-36632", "namespace": "nvd:cpe", "severity": "High", "urls": ["https://docs.python.org/3/library/email.html", "https://docs.python.org/3/library/email.utils.html", "https://github.com/Daybreak2019/PoC_python3.9_Vul/blob/main/RecursionError-email.utils.parseaddr.py", "https://github.com/python/cpython/issues/103800", "https://docs.python.org/3/library/email.html", "https://docs.python.org/3/library/email.utils.html", "https://github.com/Daybreak2019/PoC_python3.9_Vul/blob/main/RecursionError-email.utils.parseaddr.py", "https://github.com/python/cpython/issues/103800"], "description": "The legacy email.utils.parseaddr function in Python through 3.11.4 allows attackers to trigger \"RecursionError: maximum recursion depth exceeded while calling a Python object\" via a crafted argument. This argument is plausibly an untrusted value from an application's input data that was supposed to contain a name and an e-mail address. NOTE: email.utils.parseaddr is categorized as a Legacy API in the documentation of the Python email package. Applications should instead use the email.parser.BytesParser or email.parser.Parser class. NOTE: the vendor's perspective is that this is neither a vulnerability nor a bug. The email package is intended to have size limits and to throw an exception when limits are exceeded; they were exceeded by the example demonstration code.", "cvss": [{"version": "3.1", "vector": "CVSS:3.1/AV:N/AC:L/PR:N/UI:N/S:U/C:N/I:N/A:H", "metrics": {"baseScore": 7.5, "exploitabilityScore": 3.9, "impactScore": 3.6}, "vendorMetadata": {}}], "fix": {"versions": null, "state": ""}, "advisories": null}, "relatedVulnerabilities": null, "matchDetails": [{"type": "cpe-match", "matcher": "stock-matcher", "searchedBy": {"namespace": "nvd:cpe", "cpes": ["cpe:2.3:a:python:python:3.11.3:*:*:*:*:*:*:*"], "package": {"name": "python", "version": "3.11.3"}}, "found": {"vulnerabilityID": "CVE-2023-36632", "versionConstraint": "<= 3.11.4 (unknown)", "cpes": ["cpe:2.3:a:python:python:*:*:*:*:*:*:*:*"]}}], "artifact": {"name": "python", "version": "3.11.3", "type": "binary", "locations": [{"path": "/usr/local/lib/libpython3.11.so.1.0", "layerID": "sha256:8e0e498514c61f26d96e7289ba2cbda125238188f34251c3ac9ae542e5164cb8"}, {"path": "/usr/local/bin/python3.11", "layerID": "sha256:8e0e498514c61f26d96e7289ba2cbda125238188f34251c3ac9ae542e5164cb8"}], "language": "", "licenses": null, "cpes": ["cpe:2.3:a:python_software_foundation:python:3.11.3:*:*:*:*:*:*:*", "cpe:2.3:a:python:python:3.11.3:*:*:*:*:*:*:*"], "purl": "pkg:generic/python@3.11.3", "upstreams": null}}, {"vulnerability": {"id": "CVE-2025-4435", "dataSource": "https://nvd.nist.gov/vuln/detail/CVE-2025-4435", "namespace": "nvd:cpe", "severity": "High", "urls": ["https://github.com/python/cpython/commit/19de092debb3d7e832e5672cc2f7b788d35951da", "https://github.com/python/cpython/commit/28463dba112af719df1e8b0391c46787ad756dd9", "https://github.com/python/cpython/commit/3612d8f51741b11f36f8fb0494d79086bac9390a", "https://github.com/python/cpython/commit/4633f3f497b1ff70e4a35b6fe2c907cbe2d4cb2e", "https://github.com/python/cpython/commit/9c1110ef6652687d7c55f590f909720eddde965a", "https://github.com/python/cpython/commit/9e0ac76d96cf80b49055f6d6b9a6763fb9215c2a", "https://github.com/python/cpython/commit/aa9eb5f757ceff461e6e996f12c89e5d9b583b01", "https://github.com/python/cpython/commit/dd8f187d0746da151e0025c51680979ac5b4cfb1", "https://github.com/python/cpython/issues/135034", "https://github.com/python/cpython/pull/135037", "https://mail.python.org/archives/list/security-announce@python.org/thread/MAXIJJCUUMCL7ATZNDVEGGHUMQMUUKLG/"], "description": "When using a TarFile.errorlevel = 0\u00a0and extracting with a filter the documented behavior is that any filtered members would be skipped and not extracted. However the actual behavior of TarFile.errorlevel = 0\u00a0in affected versions is that the member would still be extracted and not skipped.", "cvss": [{"version": "3.1", "vector": "CVSS:3.1/AV:N/AC:L/PR:N/UI:N/S:U/C:N/I:H/A:N", "metrics": {"baseScore": 7.5, "exploitabilityScore": 3.9, "impactScore": 3.6}, "vendorMetadata": {}}], "fix": {"versions": ["3.9.23", "3.10.18", "3.11.13", "3.12.11", "3.13.4", "3.14.0b3"], "state": "fixed"}, "advisories": null}, "relatedVulnerabilities": null, "matchDetails": [{"type": "cpe-match", "matcher": "stock-matcher", "searchedBy": {"namespace": "nvd:cpe", "cpes": ["cpe:2.3:a:python:python:3.11.3:*:*:*:*:*:*:*"], "package": {"name": "python", "version": "3.11.3"}}, "found": {"vulnerabilityID": "CVE-2025-4435", "versionConstraint": "< 3.9.23,>= 3.10.0, < 3.10.18,>= 3.11.0, < 3.11.13,>= 3.12.0, < 3.12.11,>= 3.13.0, < 3.13.4,>= 3.14.0a1, < 3.14.0b3 (unknown)", "cpes": ["cpe:2.3:a:python:python:*:*:*:*:*:*:*:*"]}}], "artifact": {"name": "python", "version": "3.11.3", "type": "binary", "locations": [{"path": "/usr/local/lib/libpython3.11.so.1.0", "layerID": "sha256:8e0e498514c61f26d96e7289ba2cbda125238188f34251c3ac9ae542e5164cb8"}, {"path": "/usr/local/bin/python3.11", "layerID": "sha256:8e0e498514c61f26d96e7289ba2cbda125238188f34251c3ac9ae542e5164cb8"}], "language": "", "licenses": null, "cpes": ["cpe:2.3:a:python_software_foundation:python:3.11.3:*:*:*:*:*:*:*", "cpe:2.3:a:python:python:3.11.3:*:*:*:*:*:*:*"], "purl": "pkg:generic/python@3.11.3", "upstreams": null}}, {"vulnerability": {"id": "CVE-2024-12718", "dataSource": "https://nvd.nist.gov/vuln/detail/CVE-2024-12718", "namespace": "nvd:cpe", "severity": "Medium", "urls": ["https://gist.github.com/sethmlarson/52398e33eff261329a0180ac1d54f42f", "https://github.com/python/cpython/commit/19de092debb3d7e832e5672cc2f7b788d35951da", "https://github.com/python/cpython/commit/28463dba112af719df1e8b0391c46787ad756dd9", "https://github.com/python/cpython/commit/3612d8f51741b11f36f8fb0494d79086bac9390a", "https://github.com/python/cpython/commit/4633f3f497b1ff70e4a35b6fe2c907cbe2d4cb2e", "https://github.com/python/cpython/commit/9c1110ef6652687d7c55f590f909720eddde965a", "https://github.com/python/cpython/commit/9e0ac76d96cf80b49055f6d6b9a6763fb9215c2a", "https://github.com/python/cpython/commit/aa9eb5f757ceff461e6e996f12c89e5d9b583b01", "https://github.com/python/cpython/commit/dd8f187d0746da151e0025c51680979ac5b4cfb1", "https://github.com/python/cpython/issues/127987", "https://github.com/python/cpython/issues/135034", "https://github.com/python/cpython/pull/135037", "https://mail.python.org/archives/list/security-announce@python.org/thread/MAXIJJCUUMCL7ATZNDVEGGHUMQMUUKLG/", "https://github.com/python/cpython/issues/127987"], "description": "Allows modifying some file metadata (e.g. last modified) with filter=\"data\"\u00a0or file permissions (chmod) with filter=\"tar\"\u00a0of files outside the extraction directory.\nYou are affected by this vulnerability if using the tarfile\u00a0module to extract untrusted tar archives using TarFile.extractall()\u00a0or TarFile.extract()\u00a0using the filter=\u00a0parameter with a value of \"data\"\u00a0or \"tar\". See the tarfile  extraction filters documentation https://docs.python.org/3/library/tarfile.html#tarfile-extraction-filter \u00a0for more information. Only Python versions 3.12 or later are affected by these vulnerabilities, earlier versions don't include the extraction filter feature.\n\nNote that for Python 3.14 or later the default value of filter=\u00a0changed from \"no filtering\" to `\"data\", so if you are relying on this new default behavior then your usage is also affected.\n\nNote that none of these vulnerabilities significantly affect the installation of source distributions which are tar archives as source distributions already allow arbitrary code execution during the build process. However when evaluating source distributions it's important to avoid installing source distributions with suspicious links.", "cvss": [{"version": "3.1", "vector": "CVSS:3.1/AV:N/AC:L/PR:N/UI:N/S:U/C:N/I:L/A:N", "metrics": {"baseScore": 5.3, "exploitabilityScore": 3.9, "impactScore": 1.5}, "vendorMetadata": {}}], "fix": {"versions": ["3.9.23", "3.10.18", "3.11.13", "3.12.11", "3.13.4", "3.14.0b3"], "state": "fixed"}, "advisories": null}, "relatedVulnerabilities": null, "matchDetails": [{"type": "cpe-match", "matcher": "stock-matcher", "searchedBy": {"namespace": "nvd:cpe", "cpes": ["cpe:2.3:a:python:python:3.11.3:*:*:*:*:*:*:*"], "package": {"name": "python", "version": "3.11.3"}}, "found": {"vulnerabilityID": "CVE-2024-12718", "versionConstraint": "< 3.9.23,>= 3.10.0, < 3.10.18,>= 3.11.0, < 3.11.13,>= 3.12.0, < 3.12.11,>= 3.13.0, < 3.13.4,>= 3.14.0a1, < 3.14.0b3 (unknown)", "cpes": ["cpe:2.3:a:python:python:*:*:*:*:*:*:*:*"]}}], "artifact": {"name": "python", "version": "3.11.3", "type": "binary", "locations": [{"path": "/usr/local/lib/libpython3.11.so.1.0", "layerID": "sha256:8e0e498514c61f26d96e7289ba2cbda125238188f34251c3ac9ae542e5164cb8"}, {"path": "/usr/local/bin/python3.11", "layerID": "sha256:8e0e498514c61f26d96e7289ba2cbda125238188f34251c3ac9ae542e5164cb8"}], "language": "", "licenses": null, "cpes": ["cpe:2.3:a:python_software_foundation:python:3.11.3:*:*:*:*:*:*:*", "cpe:2.3:a:python:python:3.11.3:*:*:*:*:*:*:*"], "purl": "pkg:generic/python@3.11.3", "upstreams": null}}, {"vulnerability": {"id": "CVE-2025-1795", "dataSource": "https://nvd.nist.gov/vuln/detail/CVE-2025-1795", "namespace": "nvd:cpe", "severity": "Low", "urls": ["https://github.com/python/cpython/commit/09fab93c3d857496c0bd162797fab816c311ee48", "https://github.com/python/cpython/commit/70754d21c288535e86070ca7a6e90dcb670b8593", "https://github.com/python/cpython/commit/9148b77e0af91cdacaa7fe3dfac09635c3fe9a74", "https://github.com/python/cpython/issues/100884", "https://github.com/python/cpython/pull/100885", "https://github.com/python/cpython/pull/119099", "https://mail.python.org/archives/list/security-announce@python.org/thread/MB62IZMEC3UM6SGHP5LET5JX2Y7H4ZUR/"], "description": "During an address list folding when a separating comma ends up on a folded line and that line is to be unicode-encoded then the separator itself is also unicode-encoded. Expected behavior is that the separating comma remains a plan comma. This can result in the address header being misinterpreted by some mail servers.", "cvss": [{"version": "4.0", "vector": "CVSS:4.0/AV:N/AC:H/AT:P/PR:L/UI:N/VC:L/VI:N/VA:N/SC:N/SI:N/SA:N/E:X/CR:X/IR:X/AR:X/MAV:X/MAC:X/MAT:X/MPR:X/MUI:X/MVC:X/MVI:X/MVA:X/MSC:X/MSI:X/MSA:X/S:X/AU:X/R:X/V:X/RE:X/U:X", "metrics": {"baseScore": 2.3}, "vendorMetadata": {}}], "fix": {"versions": ["3.11.9", "3.12.3", "3.13.0a5"], "state": "fixed"}, "advisories": null}, "relatedVulnerabilities": null, "matchDetails": [{"type": "cpe-match", "matcher": "stock-matcher", "searchedBy": {"namespace": "nvd:cpe", "cpes": ["cpe:2.3:a:python:python:3.11.3:*:*:*:*:*:*:*"], "package": {"name": "python", "version": "3.11.3"}}, "found": {"vulnerabilityID": "CVE-2025-1795", "versionConstraint": "< 3.11.9,>= 3.12.0, < 3.12.3,>= 3.13.0a1, < 3.13.0a5 (unknown)", "cpes": ["cpe:2.3:a:python:python:*:*:*:*:*:*:*:*"]}}], "artifact": {"name": "python", "version": "3.11.3", "type": "binary", "locations": [{"path": "/usr/local/lib/libpython3.11.so.1.0", "layerID": "sha256:8e0e498514c61f26d96e7289ba2cbda125238188f34251c3ac9ae542e5164cb8"}, {"path": "/usr/local/bin/python3.11", "layerID": "sha256:8e0e498514c61f26d96e7289ba2cbda125238188f34251c3ac9ae542e5164cb8"}], "language": "", "licenses": null, "cpes": ["cpe:2.3:a:python_software_foundation:python:3.11.3:*:*:*:*:*:*:*", "cpe:2.3:a:python:python:3.11.3:*:*:*:*:*:*:*"], "purl": "pkg:generic/python@3.11.3", "upstreams": null}}, {"vulnerability": {"id": "CVE-2025-6069", "dataSource": "https://nvd.nist.gov/vuln/detail/CVE-2025-6069", "namespace": "nvd:cpe", "severity": "Medium", "urls": ["https://github.com/python/cpython/commit/4455cbabf991e202185a25a631af206f60bbc949", "https://github.com/python/cpython/commit/6eb6c5dbfb528bd07d77b60fd71fd05d81d45c41", "https://github.com/python/cpython/commit/8d1b3dfa09135affbbf27fb8babcf3c11415df49", "https://github.com/python/cpython/commit/ab0893fd5c579d9cea30841680e6d35fc478afb5", "https://github.com/python/cpython/commit/d851f8e258c7328814943e923a7df81bca15df4b", "https://github.com/python/cpython/commit/f3c6f882cddc8dc30320d2e73edf019e201394fc", "https://github.com/python/cpython/commit/fdc9d214c01cb4588f540cfa03726bbf2a33fc15", "https://github.com/python/cpython/issues/135462", "https://github.com/python/cpython/pull/135464", "https://mail.python.org/archives/list/security-announce@python.org/thread/K5PIYLR6EP3WR7ZOKKYQUWEDNQVUXOYM/"], "description": "The html.parser.HTMLParser class had worse-case quadratic complexity when processing certain crafted malformed inputs potentially leading to amplified denial-of-service.", "cvss": [{"version": "3.1", "vector": "CVSS:3.1/AV:N/AC:L/PR:L/UI:N/S:U/C:N/I:N/A:L", "metrics": {"baseScore": 4.3, "exploitabilityScore": 2.9, "impactScore": 1.5}, "vendorMetadata": {}}], "fix": {"versions": ["3.13.6", "3.14.0b3"], "state": "fixed"}, "advisories": null}, "relatedVulnerabilities": null, "matchDetails": [{"type": "cpe-match", "matcher": "stock-matcher", "searchedBy": {"namespace": "nvd:cpe", "cpes": ["cpe:2.3:a:python:python:3.11.3:*:*:*:*:*:*:*"], "package": {"name": "python", "version": "3.11.3"}}, "found": {"vulnerabilityID": "CVE-2025-6069", "versionConstraint": "< 3.13.6,>= 3.14.0a1, < 3.14.0b3 (unknown)", "cpes": ["cpe:2.3:a:python:python:*:*:*:*:*:*:*:*"]}}], "artifact": {"name": "python", "version": "3.11.3", "type": "binary", "locations": [{"path": "/usr/local/lib/libpython3.11.so.1.0", "layerID": "sha256:8e0e498514c61f26d96e7289ba2cbda125238188f34251c3ac9ae542e5164cb8"}, {"path": "/usr/local/bin/python3.11", "layerID": "sha256:8e0e498514c61f26d96e7289ba2cbda125238188f34251c3ac9ae542e5164cb8"}], "language": "", "licenses": null, "cpes": ["cpe:2.3:a:python_software_foundation:python:3.11.3:*:*:*:*:*:*:*", "cpe:2.3:a:python:python:3.11.3:*:*:*:*:*:*:*"], "purl": "pkg:generic/python@3.11.3", "upstreams": null}}, {"vulnerability": {"id": "CVE-2024-50602", "dataSource": "https://nvd.nist.gov/vuln/detail/CVE-2024-50602", "namespace": "nvd:cpe", "severity": "Medium", "urls": ["https://github.com/libexpat/libexpat/pull/915", "https://lists.debian.org/debian-lts-announce/2025/04/msg00040.html", "https://security.netapp.com/advisory/ntap-20250404-0008/"], "description": "An issue was discovered in libexpat before 2.6.4. There is a crash within the XML_ResumeParser function because XML_StopParser can stop/suspend an unstarted parser.", "cvss": [{"version": "3.1", "vector": "CVSS:3.1/AV:N/AC:H/PR:N/UI:N/S:U/C:N/I:N/A:H", "metrics": {"baseScore": 5.9, "exploitabilityScore": 2.3, "impactScore": 3.6}, "vendorMetadata": {}}], "fix": {"versions": ["3.9.21", "3.10.16", "3.11.11", "3.12.8", "3.13.1"], "state": "fixed"}, "advisories": null}, "relatedVulnerabilities": null, "matchDetails": [{"type": "cpe-match", "matcher": "stock-matcher", "searchedBy": {"namespace": "nvd:cpe", "cpes": ["cpe:2.3:a:python:python:3.11.3:*:*:*:*:*:*:*"], "package": {"name": "python", "version": "3.11.3"}}, "found": {"vulnerabilityID": "CVE-2024-50602", "versionConstraint": "< 3.9.21,>= 3.10, < 3.10.16,>= 3.11, < 3.11.11,>= 3.12, < 3.12.8,>= 3.13, < 3.13.1 (unknown)", "cpes": ["cpe:2.3:a:python:python:*:*:*:*:*:*:*:*"]}}], "artifact": {"name": "python", "version": "3.11.3", "type": "binary", "locations": [{"path": "/usr/local/lib/libpython3.11.so.1.0", "layerID": "sha256:8e0e498514c61f26d96e7289ba2cbda125238188f34251c3ac9ae542e5164cb8"}, {"path": "/usr/local/bin/python3.11", "layerID": "sha256:8e0e498514c61f26d96e7289ba2cbda125238188f34251c3ac9ae542e5164cb8"}], "language": "", "licenses": null, "cpes": ["cpe:2.3:a:python_software_foundation:python:3.11.3:*:*:*:*:*:*:*", "cpe:2.3:a:python:python:3.11.3:*:*:*:*:*:*:*"], "purl": "pkg:generic/python@3.11.3", "upstreams": null}}, {"vulnerability": {"id": "CVE-2024-9287", "dataSource": "https://nvd.nist.gov/vuln/detail/CVE-2024-9287", "namespace": "nvd:cpe", "severity": "High", "urls": ["https://github.com/python/cpython/commit/633555735a023d3e4d92ba31da35b1205f9ecbd7", "https://github.com/python/cpython/commit/8450b2482586857d689b6658f08de9c8179af7db", "https://github.com/python/cpython/commit/9286ab3a107ea41bd3f3c3682ce2512692bdded8", "https://github.com/python/cpython/commit/ae961ae94bf19c8f8c7fbea3d1c25cc55ce8ae97", "https://github.com/python/cpython/commit/d48cc82ed25e26b02eb97c6263d95dcaa1e9111b", "https://github.com/python/cpython/commit/e52095a0c1005a87eed2276af7a1f2f66e2b6483", "https://github.com/python/cpython/issues/124651", "https://github.com/python/cpython/pull/124712", "https://mail.python.org/archives/list/security-announce@python.org/thread/RSPJ2B5JL22FG3TKUJ7D7DQ4N5JRRBZL/", "https://security.netapp.com/advisory/ntap-20250425-0006/"], "description": "A vulnerability has been found in the CPython `venv` module and CLI where path names provided when creating a virtual environment were not quoted properly, allowing the creator to inject commands into virtual environment \"activation\" scripts (ie \"source venv/bin/activate\"). This means that attacker-controlled virtual environments are able to run commands when the virtual environment is activated. Virtual environments which are not created by an attacker or which aren't activated before being used (ie \"./venv/bin/python\") are not affected.", "cvss": [{"version": "3.1", "vector": "CVSS:3.1/AV:L/AC:L/PR:L/UI:N/S:U/C:H/I:H/A:H", "metrics": {"baseScore": 7.8, "exploitabilityScore": 1.9, "impactScore": 5.9}, "vendorMetadata": {}}, {"version": "4.0", "vector": "CVSS:4.0/AV:L/AC:L/AT:P/PR:H/UI:A/VC:H/VI:H/VA:N/SC:N/SI:N/SA:N/E:X/CR:X/IR:X/AR:X/MAV:X/MAC:X/MAT:X/MPR:X/MUI:X/MVC:X/MVI:X/MVA:X/MSC:X/MSI:X/MSA:X/S:X/AU:X/R:X/V:X/RE:X/U:Green", "metrics": {"baseScore": 5.3}, "vendorMetadata": {}}], "fix": {"versions": ["3.9.21", "3.10.16", "3.11.11", "3.12.8", "3.13.1", "3.14.0a2"], "state": "fixed"}, "advisories": null}, "relatedVulnerabilities": null, "matchDetails": [{"type": "cpe-match", "matcher": "stock-matcher", "searchedBy": {"namespace": "nvd:cpe", "cpes": ["cpe:2.3:a:python:python:3.11.3:*:*:*:*:*:*:*"], "package": {"name": "python", "version": "3.11.3"}}, "found": {"vulnerabilityID": "CVE-2024-9287", "versionConstraint": "< 3.9.21,>= 3.10.0, < 3.10.16,>= 3.11.0, < 3.11.11,>= 3.12.0, < 3.12.8,>= 3.13.0, < 3.13.1,>= 3.14.0a1, < 3.14.0a2 (unknown)", "cpes": ["cpe:2.3:a:python:python:*:*:*:*:*:*:*:*"]}}], "artifact": {"name": "python", "version": "3.11.3", "type": "binary", "locations": [{"path": "/usr/local/lib/libpython3.11.so.1.0", "layerID": "sha256:8e0e498514c61f26d96e7289ba2cbda125238188f34251c3ac9ae542e5164cb8"}, {"path": "/usr/local/bin/python3.11", "layerID": "sha256:8e0e498514c61f26d96e7289ba2cbda125238188f34251c3ac9ae542e5164cb8"}], "language": "", "licenses": null, "cpes": ["cpe:2.3:a:python_software_foundation:python:3.11.3:*:*:*:*:*:*:*", "cpe:2.3:a:python:python:3.11.3:*:*:*:*:*:*:*"], "purl": "pkg:generic/python@3.11.3", "upstreams": null}}, {"vulnerability": {"id": "CVE-2025-4516", "dataSource": "https://nvd.nist.gov/vuln/detail/CVE-2025-4516", "namespace": "nvd:cpe", "severity": "Medium", "urls": ["https://github.com/python/cpython/commit/4398b788ffc1f954a2c552da285477d42a571292", "https://github.com/python/cpython/commit/6279eb8c076d89d3739a6edb393e43c7929b429d", "https://github.com/python/cpython/commit/69b4387f78f413e8c47572a85b3478c47eba8142", "https://github.com/python/cpython/commit/73b3040f592436385007918887b7e2132aa8431f", "https://github.com/python/cpython/commit/8d35fd1b34935221aff23a1ab69a429dd156be77", "https://github.com/python/cpython/commit/9f69a58623bd01349a18ba0c7a9cb1dad6a51e8e", "https://github.com/python/cpython/commit/ab9893c40609935e0d40a6d2a7307ea51aec598b", "https://github.com/python/cpython/issues/133767", "https://github.com/python/cpython/pull/129648", "https://mail.python.org/archives/list/security-announce@python.org/thread/L75IPBBTSCYEF56I2M4KIW353BB3AY74/", "http://www.openwall.com/lists/oss-security/2025/05/16/4", "http://www.openwall.com/lists/oss-security/2025/05/19/1"], "description": "There is an issue in CPython when using `bytes.decode(\"unicode_escape\", error=\"ignore|replace\")`. If you are not using the \"unicode_escape\" encoding or an error handler your usage is not affected. To work-around this issue you may stop using the error= handler and instead wrap the bytes.decode() call in a try-except catching the DecodeError.", "cvss": [{"version": "4.0", "vector": "CVSS:4.0/AV:L/AC:H/AT:P/PR:N/UI:N/VC:N/VI:N/VA:H/SC:N/SI:N/SA:N/E:X/CR:X/IR:X/AR:X/MAV:X/MAC:X/MAT:X/MPR:X/MUI:X/MVC:X/MVI:X/MVA:X/MSC:X/MSI:X/MSA:X/S:X/AU:X/R:X/V:X/RE:X/U:X", "metrics": {"baseScore": 5.9}, "vendorMetadata": {}}], "fix": {"versions": ["3.9.23", "3.10.18", "3.11.13", "3.12.11", "3.13.4", "3.14.0b2"], "state": "fixed"}, "advisories": null}, "relatedVulnerabilities": null, "matchDetails": [{"type": "cpe-match", "matcher": "stock-matcher", "searchedBy": {"namespace": "nvd:cpe", "cpes": ["cpe:2.3:a:python:python:3.11.3:*:*:*:*:*:*:*"], "package": {"name": "python", "version": "3.11.3"}}, "found": {"vulnerabilityID": "CVE-2025-4516", "versionConstraint": "< 3.9.23,>= 3.10.0, < 3.10.18,>= 3.11.0, < 3.11.13,>= 3.12.0, < 3.12.11,>= 3.13.0, < 3.13.4,>= 3.14.0a1, < 3.14.0b2 (unknown)", "cpes": ["cpe:2.3:a:python:python:*:*:*:*:*:*:*:*"]}}], "artifact": {"name": "python", "version": "3.11.3", "type": "binary", "locations": [{"path": "/usr/local/lib/libpython3.11.so.1.0", "layerID": "sha256:8e0e498514c61f26d96e7289ba2cbda125238188f34251c3ac9ae542e5164cb8"}, {"path": "/usr/local/bin/python3.11", "layerID": "sha256:8e0e498514c61f26d96e7289ba2cbda125238188f34251c3ac9ae542e5164cb8"}], "language": "", "licenses": null, "cpes": ["cpe:2.3:a:python_software_foundation:python:3.11.3:*:*:*:*:*:*:*", "cpe:2.3:a:python:python:3.11.3:*:*:*:*:*:*:*"], "purl": "pkg:generic/python@3.11.3", "upstreams": null}}], "source": {"type": "image", "target": {"userInput": "docker.io/library/python@sha256:4e8e9a59bf1b3ca8e030244bc5f801f23e41e37971907371da21191312087a07", "imageID": "sha256:b6b068cda0cf592463549591ed736c4e87a6c5404335c09e01ba5b3eb0e9970b", "manifestDigest": "", "mediaType": "", "tags": [], "imageSize": 52558943, "layers": [{"mediaType": "application/vnd.oci.image.layer.v1.tar+gzip", "digest": "sha256:1aa0efac0e6569715975eef150b375ccad0e129bd391da385991243f30d921bb", "size": 7327451}, {"mediaType": "application/vnd.oci.image.layer.v1.tar+gzip", "digest": "sha256:07c29273aae67b581150012c2df0fffbc2474ee17cf4ad75358d956dfbeef27f", "size": 2336551}, {"mediaType": "application/vnd.oci.image.layer.v1.tar+gzip", "digest": "sha256:8e0e498514c61f26d96e7289ba2cbda125238188f34251c3ac9ae542e5164cb8", "size": 31905942}, {"mediaType": "application/vnd.oci.image.layer.v1.tar+gzip", "digest": "sha256:208977ac81d79a33082babcb62e6971018ec28df3b7a2d7c8d1c4034251cfa1c", "size": 32}, {"mediaType": "application/vnd.oci.image.layer.v1.tar+gzip", "digest": "sha256:bb01bd7e32b58b6694c8c3622c230171f1cec24001a82068a8d30d338f420d6c", "size": 10988967}], "manifest": null, "config": "eyJhcmNoaXRlY3R1cmUiOiJhbWQ2NCIsImNyZWF0ZWQiOiIyMDIzLTA1LTEwVDEwOjEwOjExWiIsImhpc3RvcnkiOlt7ImNyZWF0ZWQiOiIyMDIzLTA1LTA5VDIzOjExOjEwLjAwNzIxNzU1M1oiLCJjcmVhdGVkX2J5IjoiL2Jpbi9zaCAtYyAjKG5vcCkgQUREIGZpbGU6NzYyNWRkZmQ1ODlmYjgyNGVlMzlmMWIxZWIzODdiOThmMzY3NjQyMGZmNTJmMjZlYjlkOTc1MTUxZTg4OTY2NyBpbiAvICJ9LHsiY3JlYXRlZCI6IjIwMjMtMDUtMDlUMjM6MTE6MTAuMTMyMTQ3NTI2WiIsImNyZWF0ZWRfYnkiOiIvYmluL3NoIC1jICMobm9wKSAgQ01EIFtcIi9iaW4vc2hcIl0iLCJlbXB0eV9sYXllciI6dHJ1ZX0seyJjcmVhdGVkIjoiMjAyMy0wNS0xMFQxMDoxMDoxMVoiLCJjcmVhdGVkX2J5IjoiRU5WIFBBVEg9L3Vzci9sb2NhbC9iaW46L3Vzci9sb2NhbC9zYmluOi91c3IvbG9jYWwvYmluOi91c3Ivc2JpbjovdXNyL2Jpbjovc2JpbjovYmluIiwiY29tbWVudCI6ImJ1aWxka2l0LmRvY2tlcmZpbGUudjAiLCJlbXB0eV9sYXllciI6dHJ1ZX0seyJjcmVhdGVkIjoiMjAyMy0wNS0xMFQxMDoxMDoxMVoiLCJjcmVhdGVkX2J5IjoiRU5WIExBTkc9Qy5VVEYtOCIsImNvbW1lbnQiOiJidWlsZGtpdC5kb2NrZXJmaWxlLnYwIiwiZW1wdHlfbGF5ZXIiOnRydWV9LHsiY3JlYXRlZCI6IjIwMjMtMDUtMTBUMTA6MTA6MTFaIiwiY3JlYXRlZF9ieSI6IlJVTiAvYmluL3NoIC1jIHNldCAtZXV4OyBcdGFwayBhZGQgLS1uby1jYWNoZSBcdFx0Y2EtY2VydGlmaWNhdGVzIFx0XHR0emRhdGEgXHQ7ICMgYnVpbGRraXQiLCJjb21tZW50IjoiYnVpbGRraXQuZG9ja2VyZmlsZS52MCJ9LHsiY3JlYXRlZCI6IjIwMjMtMDUtMTBUMTA6MTA6MTFaIiwiY3JlYXRlZF9ieSI6IkVOViBHUEdfS0VZPUEwMzVDOEMxOTIxOUJBODIxRUNFQTg2QjY0RTYyOEY4RDY4NDY5NkQiLCJjb21tZW50IjoiYnVpbGRraXQuZG9ja2VyZmlsZS52MCIsImVtcHR5X2xheWVyIjp0cnVlfSx7ImNyZWF0ZWQiOiIyMDIzLTA1LTEwVDEwOjEwOjExWiIsImNyZWF0ZWRfYnkiOiJFTlYgUFlUSE9OX1ZFUlNJT049My4xMS4zIiwiY29tbWVudCI6ImJ1aWxka2l0LmRvY2tlcmZpbGUudjAiLCJlbXB0eV9sYXllciI6dHJ1ZX0seyJjcmVhdGVkIjoiMjAyMy0wNS0xMFQxMDoxMDoxMVoiLCJjcmVhdGVkX2J5IjoiUlVOIC9iaW4vc2ggLWMgc2V0IC1ldXg7IFx0XHRhcGsgYWRkIC0tbm8tY2FjaGUgLS12aXJ0dWFsIC5idWlsZC1kZXBzIFx0XHRnbnVwZyBcdFx0dGFyIFx0XHR4eiBcdFx0XHRcdGJsdWV6LWRldiBcdFx0YnppcDItZGV2IFx0XHRkcGtnLWRldiBkcGtnIFx0XHRleHBhdC1kZXYgXHRcdGZpbmR1dGlscyBcdFx0Z2NjIFx0XHRnZGJtLWRldiBcdFx0bGliYy1kZXYgXHRcdGxpYmZmaS1kZXYgXHRcdGxpYm5zbC1kZXYgXHRcdGxpYnRpcnBjLWRldiBcdFx0bGludXgtaGVhZGVycyBcdFx0bWFrZSBcdFx0bmN1cnNlcy1kZXYgXHRcdG9wZW5zc2wtZGV2IFx0XHRwYXgtdXRpbHMgXHRcdHJlYWRsaW5lLWRldiBcdFx0c3FsaXRlLWRldiBcdFx0dGNsLWRldiBcdFx0dGsgXHRcdHRrLWRldiBcdFx0dXRpbC1saW51eC1kZXYgXHRcdHh6LWRldiBcdFx0emxpYi1kZXYgXHQ7IFx0XHR3Z2V0IC1PIHB5dGhvbi50YXIueHogXCJodHRwczovL3d3dy5weXRob24ub3JnL2Z0cC9weXRob24vJHtQWVRIT05fVkVSU0lPTiUlW2Etel0qfS9QeXRob24tJFBZVEhPTl9WRVJTSU9OLnRhci54elwiOyBcdHdnZXQgLU8gcHl0aG9uLnRhci54ei5hc2MgXCJodHRwczovL3d3dy5weXRob24ub3JnL2Z0cC9weXRob24vJHtQWVRIT05fVkVSU0lPTiUlW2Etel0qfS9QeXRob24tJFBZVEhPTl9WRVJTSU9OLnRhci54ei5hc2NcIjsgXHRHTlVQR0hPTUU9XCIkKG1rdGVtcCAtZClcIjsgZXhwb3J0IEdOVVBHSE9NRTsgXHRncGcgLS1iYXRjaCAtLWtleXNlcnZlciBoa3BzOi8va2V5cy5vcGVucGdwLm9yZyAtLXJlY3Yta2V5cyBcIiRHUEdfS0VZXCI7IFx0Z3BnIC0tYmF0Y2ggLS12ZXJpZnkgcHl0aG9uLnRhci54ei5hc2MgcHl0aG9uLnRhci54ejsgXHRncGdjb25mIC0ta2lsbCBhbGw7IFx0cm0gLXJmIFwiJEdOVVBHSE9NRVwiIHB5dGhvbi50YXIueHouYXNjOyBcdG1rZGlyIC1wIC91c3Ivc3JjL3B5dGhvbjsgXHR0YXIgLS1leHRyYWN0IC0tZGlyZWN0b3J5IC91c3Ivc3JjL3B5dGhvbiAtLXN0cmlwLWNvbXBvbmVudHM9MSAtLWZpbGUgcHl0aG9uLnRhci54ejsgXHRybSBweXRob24udGFyLnh6OyBcdFx0Y2QgL3Vzci9zcmMvcHl0aG9uOyBcdGdudUFyY2g9XCIkKGRwa2ctYXJjaGl0ZWN0dXJlIC0tcXVlcnkgREVCX0JVSUxEX0dOVV9UWVBFKVwiOyBcdC4vY29uZmlndXJlIFx0XHQtLWJ1aWxkPVwiJGdudUFyY2hcIiBcdFx0LS1lbmFibGUtbG9hZGFibGUtc3FsaXRlLWV4dGVuc2lvbnMgXHRcdC0tZW5hYmxlLW9wdGltaXphdGlvbnMgXHRcdC0tZW5hYmxlLW9wdGlvbi1jaGVja2luZz1mYXRhbCBcdFx0LS1lbmFibGUtc2hhcmVkIFx0XHQtLXdpdGgtbHRvIFx0XHQtLXdpdGgtc3lzdGVtLWV4cGF0IFx0XHQtLXdpdGhvdXQtZW5zdXJlcGlwIFx0OyBcdG5wcm9jPVwiJChucHJvYylcIjsgXHRFWFRSQV9DRkxBR1M9XCItRFRIUkVBRF9TVEFDS19TSVpFPTB4MTAwMDAwXCI7IFx0TERGTEFHUz1cIiR7TERGTEFHUzotLVdsfSwtLXN0cmlwLWFsbFwiOyBcdG1ha2UgLWogXCIkbnByb2NcIiBcdFx0XCJFWFRSQV9DRkxBR1M9JHtFWFRSQV9DRkxBR1M6LX1cIiBcdFx0XCJMREZMQUdTPSR7TERGTEFHUzotfVwiIFx0XHRcIlBST0ZJTEVfVEFTSz0ke1BST0ZJTEVfVEFTSzotfVwiIFx0OyBcdHJtIHB5dGhvbjsgXHRtYWtlIC1qIFwiJG5wcm9jXCIgXHRcdFwiRVhUUkFfQ0ZMQUdTPSR7RVhUUkFfQ0ZMQUdTOi19XCIgXHRcdFwiTERGTEFHUz0ke0xERkxBR1M6LS1XbH0sLXJwYXRoPSdcXCRcXCRPUklHSU4vLi4vbGliJ1wiIFx0XHRcIlBST0ZJTEVfVEFTSz0ke1BST0ZJTEVfVEFTSzotfVwiIFx0XHRweXRob24gXHQ7IFx0bWFrZSBpbnN0YWxsOyBcdFx0Y2QgLzsgXHRybSAtcmYgL3Vzci9zcmMvcHl0aG9uOyBcdFx0ZmluZCAvdXNyL2xvY2FsIC1kZXB0aCBcdFx0XFwoIFx0XHRcdFxcKCAtdHlwZSBkIC1hIFxcKCAtbmFtZSB0ZXN0IC1vIC1uYW1lIHRlc3RzIC1vIC1uYW1lIGlkbGVfdGVzdCBcXCkgXFwpIFx0XHRcdC1vIFxcKCAtdHlwZSBmIC1hIFxcKCAtbmFtZSAnKi5weWMnIC1vIC1uYW1lICcqLnB5bycgLW8gLW5hbWUgJ2xpYnB5dGhvbiouYScgXFwpIFxcKSBcdFx0XFwpIC1leGVjIHJtIC1yZiAne30nICsgXHQ7IFx0XHRmaW5kIC91c3IvbG9jYWwgLXR5cGUgZiAtZXhlY3V0YWJsZSAtbm90IFxcKCAtbmFtZSAnKnRraW50ZXIqJyBcXCkgLWV4ZWMgc2NhbmVsZiAtLW5lZWRlZCAtLW5vYmFubmVyIC0tZm9ybWF0ICclbiNwJyAne30nICc7JyBcdFx0fCB0ciAnLCcgJ1xcbicgXHRcdHwgc29ydCAtdSBcdFx0fCBhd2sgJ3N5c3RlbShcIlsgLWUgL3Vzci9sb2NhbC9saWIvXCIgJDEgXCIgXVwiKSA9PSAwIHsgbmV4dCB9IHsgcHJpbnQgXCJzbzpcIiAkMSB9JyBcdFx0fCB4YXJncyAtcnQgYXBrIGFkZCAtLW5vLW5ldHdvcmsgLS12aXJ0dWFsIC5weXRob24tcnVuZGVwcyBcdDsgXHRhcGsgZGVsIC0tbm8tbmV0d29yayAuYnVpbGQtZGVwczsgXHRcdHB5dGhvbjMgLS12ZXJzaW9uICMgYnVpbGRraXQiLCJjb21tZW50IjoiYnVpbGRraXQuZG9ja2VyZmlsZS52MCJ9LHsiY3JlYXRlZCI6IjIwMjMtMDUtMTBUMTA6MTA6MTFaIiwiY3JlYXRlZF9ieSI6IlJVTiAvYmluL3NoIC1jIHNldCAtZXV4OyBcdGZvciBzcmMgaW4gaWRsZTMgcHlkb2MzIHB5dGhvbjMgcHl0aG9uMy1jb25maWc7IGRvIFx0XHRkc3Q9XCIkKGVjaG8gXCIkc3JjXCIgfCB0ciAtZCAzKVwiOyBcdFx0WyAtcyBcIi91c3IvbG9jYWwvYmluLyRzcmNcIiBdOyBcdFx0WyAhIC1lIFwiL3Vzci9sb2NhbC9iaW4vJGRzdFwiIF07IFx0XHRsbiAtc3ZUIFwiJHNyY1wiIFwiL3Vzci9sb2NhbC9iaW4vJGRzdFwiOyBcdGRvbmUgIyBidWlsZGtpdCIsImNvbW1lbnQiOiJidWlsZGtpdC5kb2NrZXJmaWxlLnYwIn0seyJjcmVhdGVkIjoiMjAyMy0wNS0xMFQxMDoxMDoxMVoiLCJjcmVhdGVkX2J5IjoiRU5WIFBZVEhPTl9QSVBfVkVSU0lPTj0yMi4zLjEiLCJjb21tZW50IjoiYnVpbGRraXQuZG9ja2VyZmlsZS52MCIsImVtcHR5X2xheWVyIjp0cnVlfSx7ImNyZWF0ZWQiOiIyMDIzLTA1LTEwVDEwOjEwOjExWiIsImNyZWF0ZWRfYnkiOiJFTlYgUFlUSE9OX1NFVFVQVE9PTFNfVkVSU0lPTj02NS41LjEiLCJjb21tZW50IjoiYnVpbGRraXQuZG9ja2VyZmlsZS52MCIsImVtcHR5X2xheWVyIjp0cnVlfSx7ImNyZWF0ZWQiOiIyMDIzLTA1LTEwVDEwOjEwOjExWiIsImNyZWF0ZWRfYnkiOiJFTlYgUFlUSE9OX0dFVF9QSVBfVVJMPWh0dHBzOi8vZ2l0aHViLmNvbS9weXBhL2dldC1waXAvcmF3LzBkODU3MGRjNDQ3OTZmNDM2OWI2NTIyMjJjZjE3NmIzZGI2YWM3MGUvcHVibGljL2dldC1waXAucHkiLCJjb21tZW50IjoiYnVpbGRraXQuZG9ja2VyZmlsZS52MCIsImVtcHR5X2xheWVyIjp0cnVlfSx7ImNyZWF0ZWQiOiIyMDIzLTA1LTEwVDEwOjEwOjExWiIsImNyZWF0ZWRfYnkiOiJFTlYgUFlUSE9OX0dFVF9QSVBfU0hBMjU2PTk2NDYxZGVjZWQ1YzJhNDg3ZGRjNjUyMDdlYzVhOWNmZmVjYTBkMzRlN2FmN2VhMWFmYzQ3MGZmMGQ3NDYyMDciLCJjb21tZW50IjoiYnVpbGRraXQuZG9ja2VyZmlsZS52MCIsImVtcHR5X2xheWVyIjp0cnVlfSx7ImNyZWF0ZWQiOiIyMDIzLTA1LTEwVDEwOjEwOjExWiIsImNyZWF0ZWRfYnkiOiJSVU4gL2Jpbi9zaCAtYyBzZXQgLWV1eDsgXHRcdHdnZXQgLU8gZ2V0LXBpcC5weSBcIiRQWVRIT05fR0VUX1BJUF9VUkxcIjsgXHRlY2hvIFwiJFBZVEhPTl9HRVRfUElQX1NIQTI1NiAqZ2V0LXBpcC5weVwiIHwgc2hhMjU2c3VtIC1jIC07IFx0XHRleHBvcnQgUFlUSE9ORE9OVFdSSVRFQllURUNPREU9MTsgXHRcdHB5dGhvbiBnZXQtcGlwLnB5IFx0XHQtLWRpc2FibGUtcGlwLXZlcnNpb24tY2hlY2sgXHRcdC0tbm8tY2FjaGUtZGlyIFx0XHQtLW5vLWNvbXBpbGUgXHRcdFwicGlwPT0kUFlUSE9OX1BJUF9WRVJTSU9OXCIgXHRcdFwic2V0dXB0b29scz09JFBZVEhPTl9TRVRVUFRPT0xTX1ZFUlNJT05cIiBcdDsgXHRybSAtZiBnZXQtcGlwLnB5OyBcdFx0cGlwIC0tdmVyc2lvbiAjIGJ1aWxka2l0IiwiY29tbWVudCI6ImJ1aWxka2l0LmRvY2tlcmZpbGUudjAifSx7ImNyZWF0ZWQiOiIyMDIzLTA1LTEwVDEwOjEwOjExWiIsImNyZWF0ZWRfYnkiOiJDTUQgW1wicHl0aG9uM1wiXSIsImNvbW1lbnQiOiJidWlsZGtpdC5kb2NrZXJmaWxlLnYwIiwiZW1wdHlfbGF5ZXIiOnRydWV9XSwib3MiOiJsaW51eCIsInJvb3RmcyI6eyJ0eXBlIjoibGF5ZXJzIiwiZGlmZl9pZHMiOlsic2hhMjU2OjFhYTBlZmFjMGU2NTY5NzE1OTc1ZWVmMTUwYjM3NWNjYWQwZTEyOWJkMzkxZGEzODU5OTEyNDNmMzBkOTIxYmIiLCJzaGEyNTY6MDdjMjkyNzNhYWU2N2I1ODExNTAwMTJjMmRmMGZmZmJjMjQ3NGVlMTdjZjRhZDc1MzU4ZDk1NmRmYmVlZjI3ZiIsInNoYTI1Njo4ZTBlNDk4NTE0YzYxZjI2ZDk2ZTcyODliYTJjYmRhMTI1MjM4MTg4ZjM0MjUxYzNhYzlhZTU0MmU1MTY0Y2I4Iiwic2hhMjU2OjIwODk3N2FjODFkNzlhMzMwODJiYWJjYjYyZTY5NzEwMThlYzI4ZGYzYjdhMmQ3YzhkMWM0MDM0MjUxY2ZhMWMiLCJzaGEyNTY6YmIwMWJkN2UzMmI1OGI2Njk0YzhjMzYyMmMyMzAxNzFmMWNlYzI0MDAxYTgyMDY4YThkMzBkMzM4ZjQyMGQ2YyJdfSwiY29uZmlnIjp7IkNtZCI6WyJweXRob24zIl0sIkhlYWx0aGNoZWNrIjp7fSwiRW52IjpbIlBBVEg9L3Vzci9sb2NhbC9iaW46L3Vzci9sb2NhbC9zYmluOi91c3IvbG9jYWwvYmluOi91c3Ivc2JpbjovdXNyL2Jpbjovc2JpbjovYmluIiwiTEFORz1DLlVURi04IiwiR1BHX0tFWT1BMDM1QzhDMTkyMTlCQTgyMUVDRUE4NkI2NEU2MjhGOEQ2ODQ2OTZEIiwiUFlUSE9OX1ZFUlNJT049My4xMS4zIiwiUFlUSE9OX1BJUF9WRVJTSU9OPTIyLjMuMSIsIlBZVEhPTl9TRVRVUFRPT0xTX1ZFUlNJT049NjUuNS4xIiwiUFlUSE9OX0dFVF9QSVBfVVJMPWh0dHBzOi8vZ2l0aHViLmNvbS9weXBhL2dldC1waXAvcmF3LzBkODU3MGRjNDQ3OTZmNDM2OWI2NTIyMjJjZjE3NmIzZGI2YWM3MGUvcHVibGljL2dldC1waXAucHkiLCJQWVRIT05fR0VUX1BJUF9TSEEyNTY9OTY0NjFkZWNlZDVjMmE0ODdkZGM2NTIwN2VjNWE5Y2ZmZWNhMGQzNGU3YWY3ZWExYWZjNDcwZmYwZDc0NjIwNyJdLCJBcmdzRXNjYXBlZCI6dHJ1ZX19", "repoDigests": ["docker.io/library/python@sha256:4e8e9a59bf1b3ca8e030244bc5f801f23e41e37971907371da21191312087a07"], "architecture": "amd64", "os": "linux"}}, "distro": {"name": "alpine", "version": "3.18.0", "idLike": null}, "descriptor": {"name": "", "version": "", "db": {"schemaVersion": "v6.1.1", "from": "http://grype-offline-db:80/databases/v6/vulnerability-db_v6.1.1_2025-09-15T01:30:11Z_1757916493.tar.zst?checksum=sha256%3A8947f666e75c337773be86e0c6f7f4739c7549184aa994ae6236d5dbe666523b", "built": "2025-09-15T06:08:13Z", "path": "/home/nonroot/.cache/grype/db/6/vulnerability.db", "valid": true}}}}, "status": {}}